Workbook

Sheet Base
A2: Producto | B2: Unidad | C2: Masa drenada | D2: Costo bruto | E2: Costo neto | F2: Código
A3: . | B3: . | C3: . | D3: . | E3: 0 | F3: 0
A4: ='Almacén '!B4 -> Producto | B4: ='Almacén '!D5 -> Kg | C4: ='Almacén '!F5 -> 1 | D4: ='Almacén '!G5 -> 24 | E4: ='Almacén '!H5 -> 24 | F4: ='Almacén '!A5 -> ABA-001
A5: ='Almacén '!B5 -> Azucár | B5: ='Almacén '!D6 -> Kg | C5: ='Almacén '!F6 -> 1 | D5: ='Almacén '!G6 -> 30 | E5: ='Almacén '!H6 -> 30 | F5: ='Almacén '!A6 -> ABA-002
A6: ='Almacén '!B7 -> Canela en polvo | B6: ='Almacén '!D7 -> Kg | C6: ='Almacén '!F7 -> 1 | D6: ='Almacén '!G7 -> 50 | E6: ='Almacén '!H7 -> 50 | F6: ='Almacén '!A7 -> ABA-003
A7: ='Almacén '!B8 | B7: ='Almacén '!D8 | C7: ='Almacén '!F8 -> 1 | D7: ='Almacén '!G8 | E7: ='Almacén '!H8 -> 0 | F7: ='Almacén '!A8 -> ABA-004
A8: ='Almacén '!B9 | B8: ='Almacén '!D9 | C8: ='Almacén '!F9 -> 1 | D8: ='Almacén '!G9 | E8: ='Almacén '!H9 -> 0 | F8: ='Almacén '!A9 -> ABA-005
A9: ='Almacén '!B10 | B9: ='Almacén '!D10 | C9: ='Almacén '!F10 -> 1 | D9: ='Almacén '!G10 | E9: ='Almacén '!H10 -> 0 | F9: ='Almacén '!A10 -> ABA-006
A10: ='Almacén '!B11 | B10: ='Almacén '!D11 | C10: ='Almacén '!F11 -> 1 | D10: ='Almacén '!G11 | E10: ='Almacén '!H11 -> 0 | F10: ='Almacén '!A11 -> ABA-007
A11: ='Almacén '!B12 | B11: ='Almacén '!D12 | C11: ='Almacén '!F12 -> 1 | D11: ='Almacén '!G12 | E11: ='Almacén '!H12 -> 0 | F11: ='Almacén '!A12 -> ABA-008
A12: ='Almacén '!B13 | B12: ='Almacén '!D13 | C12: ='Almacén '!F13 -> 1 | D12: ='Almacén '!G13 | E12: ='Almacén '!H13 -> 0 | F12: ='Almacén '!A13 -> ABA-009
A13: ='Almacén '!B14 | B13: ='Almacén '!D14 | C13: ='Almacén '!F14 -> 1 | D13: ='Almacén '!G14 | E13: ='Almacén '!H14 -> 0 | F13: ='Almacén '!A14 -> ABA-010
A14: ='Almacén '!B15 | B14: ='Almacén '!D15 | C14: ='Almacén '!F15 -> 1 | D14: ='Almacén '!G15 | E14: ='Almacén '!H15 -> 0 | F14: ='Almacén '!A15 -> ABA-011
A15: ='Almacén '!B16 | B15: ='Almacén '!D16 | C15: ='Almacén '!F16 -> 1 | D15: ='Almacén '!G16 | E15: ='Almacén '!H16 -> 0 | F15: ='Almacén '!A16 -> ABA-012
A16: ='Almacén '!B17 | B16: ='Almacén '!D17 | C16: ='Almacén '!F17 -> 1 | D16: ='Almacén '!G17 | E16: ='Almacén '!H17 -> 0 | F16: ='Almacén '!A17 -> ABA-013
A17: ='Almacén '!B18 | B17: ='Almacén '!D18 | C17: ='Almacén '!F18 -> 1 | D17: ='Almacén '!G18 | E17: ='Almacén '!H18 -> 0 | F17: ='Almacén '!A18 -> ABA-014
... A103: ='Almacén '!B104 | B103: ='Almacén '!D104 | C103: ='Almacén '!F104 -> 1 | D103: ='Almacén '!G104 | E103: ='Almacén '!H104 -> 0 | F103: ='Almacén '!A104 -> ABA-100
A104: ='Almacén '!B108 | B104: ='Almacén '!D108 | C104: ='Almacén '!G108 -> 1 | D104: ='Almacén '!H108 | E104: ='Almacén '!I108 -> 0 | F104: ='Almacén '!A108 -> FYV-001
A105: ='Almacén '!B109 | B105: ='Almacén '!D109 | C105: ='Almacén '!G109 -> 1 | D105: ='Almacén '!H109 | E105: ='Almacén '!I109 -> 0 | F105: ='Almacén '!A109 -> FYV-002
A106: ='Almacén '!B110 | B106: ='Almacén '!D110 | C106: ='Almacén '!G110 -> 1 | D106: ='Almacén '!H110 | E106: ='Almacén '!I110 -> 0 | F106: ='Almacén '!A110 -> FYV-003
A107: ='Almacén '!B111 | B107: ='Almacén '!D111 | C107: ='Almacén '!G111 -> 1 | D107: ='Almacén '!H111 | E107: ='Almacén '!I111 -> 0 | F107: ='Almacén '!A111 -> FYV-004
A108: ='Almacén '!B112 | B108: ='Almacén '!D112 | C108: ='Almacén '!G112 -> 1 | D108: ='Almacén '!H112 | E108: ='Almacén '!I112 -> 0 | F108: ='Almacén '!A112 -> FYV-005
A109: ='Almacén '!B113 | B109: ='Almacén '!D113 | C109: ='Almacén '!G113 -> 1 | D109: ='Almacén '!H113 | E109: ='Almacén '!I113 -> 0 | F109: ='Almacén '!A113 -> FYV-006
A110: ='Almacén '!B114 | B110: ='Almacén '!D114 | C110: ='Almacén '!G114 -> 1 | D110: ='Almacén '!H114 | E110: ='Almacén '!I114 -> 0 | F110: ='Almacén '!A114 -> FYV-007
A111: ='Almacén '!B115 | B111: ='Almacén '!D115 | C111: ='Almacén '!G115 -> 1 | D111: ='Almacén '!H115 | E111: ='Almacén '!I115 -> 0 | F111: ='Almacén '!A115 -> FYV-008
A112: ='Almacén '!B116 | B112: ='Almacén '!D116 | C112: ='Almacén '!G116 -> 1 | D112: ='Almacén '!H116 | E112: ='Almacén '!I116 -> 0 | F112: ='Almacén '!A116 -> FYV-009
A113: ='Almacén '!B117 | B113: ='Almacén '!D117 | C113: ='Almacén '!G117 -> 1 | D113: ='Almacén '!H117 | E113: ='Almacén '!I117 -> 0 | F113: ='Almacén '!A117 -> FYV-010
A114: ='Almacén '!B118 | B114: ='Almacén '!D118 | C114: ='Almacén '!G118 -> 1 | D114: ='Almacén '!H118 | E114: ='Almacén '!I118 -> 0 | F114: ='Almacén '!A118 -> FYV-011
A115: ='Almacén '!B119 | B115: ='Almacén '!D119 | C115: ='Almacén '!G119 -> 1 | D115: ='Almacén '!H119 | E115: ='Almacén '!I119 -> 0 | F115: ='Almacén '!A119 -> FYV-012
... A203: ='Almacén '!B207 | B203: ='Almacén '!D207 | C203: ='Almacén '!G207 -> 1 | D203: ='Almacén '!H207 | E203: ='Almacén '!I207 -> 0 | F203: ='Almacén '!A207 -> FYV-100
A204: ='Almacén '!B212 | B204: ='Almacén '!D212 | C204: ='Almacén '!G212 -> 1 | D204: ='Almacén '!H212 | E204: ='Almacén '!I212 -> 0 | F204: ='Almacén '!A212 -> RES-001
A205: ='Almacén '!B213 | B205: ='Almacén '!D213 | C205: ='Almacén '!G213 -> 1 | D205: ='Almacén '!H213 | E205: ='Almacén '!I213 -> 0 | F205: ='Almacén '!A213 -> RES-002
A206: ='Almacén '!B214 | B206: ='Almacén '!D214 | C206: ='Almacén '!G214 -> 1 | D206: ='Almacén '!H214 | E206: ='Almacén '!I214 -> 0 | F206: ='Almacén '!A214 -> RES-003
A207: ='Almacén '!B215 | B207: ='Almacén '!D215 | C207: ='Almacén '!G215 -> 1 | D207: ='Almacén '!H215 | E207: ='Almacén '!I215 -> 0 | F207: ='Almacén '!A215 -> RES-004
A208: ='Almacén '!B216 | B208: ='Almacén '!D216 | C208: ='Almacén '!G216 -> 1 | D208: ='Almacén '!H216 | E208: ='Almacén '!I216 -> 0 | F208: ='Almacén '!A216 -> RES-005
A209: ='Almacén '!B217 | B209: ='Almacén '!D217 | C209: ='Almacén '!G217 -> 1 | D209: ='Almacén '!H217 | E209: ='Almacén '!I217 -> 0 | F209: ='Almacén '!A217 -> RES-006
A210: ='Almacén '!B218 | B210: ='Almacén '!D218 | C210: ='Almacén '!G218 -> 1 | D210: ='Almacén '!H218 | E210: ='Almacén '!I218 -> 0 | F210: ='Almacén '!A218 -> RES-007
A211: ='Almacén '!B219 | B211: ='Almacén '!D219 | C211: ='Almacén '!G219 -> 1 | D211: ='Almacén '!H219 | E211: ='Almacén '!I219 -> 0 | F211: ='Almacén '!A219 -> RES-008
A212: ='Almacén '!B220 | B212: ='Almacén '!D220 | C212: ='Almacén '!G220 -> 1 | D212: ='Almacén '!H220 | E212: ='Almacén '!I220 -> 0 | F212: ='Almacén '!A220 -> RES-009
A213: ='Almacén '!B221 | B213: ='Almacén '!D221 | C213: ='Almacén '!G221 -> 1 | D213: ='Almacén '!H221 | E213: ='Almacén '!I221 -> 0 | F213: ='Almacén '!A221 -> RES-010
...

Sheet Almacén 
A1: NOMBRE DEL ESTABLECIMIENTO
I2: Inventario físico | J2: Inventario Teorico | K2: Maximo | L2: Minimo
A3: Almacén de Abarrotes y secos
A4: Código | B4: Producto | C4: Marca o proveedor | D4: Unidad | E4: Presentación de compra | F4: Masa drenada | G4: Costo Bruto | H4: Costo neto
A5: ABA-001 | B5: Azucár | C5: Morena | D5: Kg | E5: 1 | F5: 1 | G5: 24 | H5: =(G5/F5) -> 24 | I5: 50 | J5: 55 | K5: 45 | L5: 10
A6: ABA-002 | B6: Acido Citrico | C6: Citricos | D6: Kg | E6: 1 | F6: 1 | G6: 30 | H6: =(G6/F6) -> 30
A7: ABA-003 | B7: Canela en polvo | C7: Moderna | D7: Kg | E7: 1 | F7: 1 | G7: 50 | H7: =(G7/F7) -> 50
A8: ABA-004 | E8: 1 | F8: 1 | H8: =(G8/F8) -> 0
A9: ABA-005 | E9: 1 | F9: 1 | H9: =(G9/F9) -> 0
A10: ABA-006 | E10: 1 | F10: 1 | H10: =(G10/F10) -> 0
A11: ABA-007 | E11: 1 | F11: 1 | H11: =(G11/F11) -> 0
A12: ABA-008 | E12: 1 | F12: 1 | H12: =(G12/F12) -> 0
A13: ABA-009 | E13: 1 | F13: 1 | H13: =(G13/F13) -> 0
A14: ABA-010 | E14: 1 | F14: 1 | H14: =(G14/F14) -> 0
A15: ABA-011 | E15: 1 | F15: 1 | H15: =(G15/F15) -> 0
A16: ABA-012 | E16: 1 | F16: 1 | H16: =(G16/F16) -> 0
A17: ABA-013 | E17: 1 | F17: 1 | H17: =(G17/F17) -> 0
A18: ABA-014 | E18: 1 | F18: 1 | H18: =(G18/F18) -> 0
A19: ABA-015 | E19: 1 | F19: 1 | H19: =(G19/F19) -> 0
... A104: ABA-100 | E104: 1 | F104: 1 | H104: =(G104/F104) -> 0
A106: Almacén de Frutas y Verduras
A107: Código | B107: Producto | C107: Marca o proveedor | D107: Unidad | E107: % Merma | F107: Utilizable | G107: Peso neto | H107: Costo bruto | I107: Costo neto
A108: FYV-001 | F108: =100-E108 -> 100 | G108: =F108/100 -> 1 | I108: =H108/G108 -> 0
A109: FYV-002 | F109: =100-E109 -> 100 | G109: =F109/100 -> 1 | I109: =H109/G109 -> 0
A110: FYV-003 | F110: =100-E110 -> 100 | G110: =F110/100 -> 1 | I110: =H110/G110 -> 0
A111: FYV-004 | F111: =100-E111 -> 100 | G111: =F111/100 -> 1 | I111: =H111/G111 -> 0
A112: FYV-005 | F112: =100-E112 -> 100 | G112: =F112/100 -> 1 | I112: =H112/G112 -> 0
A113: FYV-006 | F113: =100-E113 -> 100 | G113: =F113/100 -> 1 | I113: =H113/G113 -> 0
A114: FYV-007 | F114: =100-E114 -> 100 | G114: =F114/100 -> 1 | I114: =H114/G114 -> 0
A115: FYV-008 | F115: =100-E115 -> 100 | G115: =F115/100 -> 1 | I115: =H115/G115 -> 0
A116: FYV-009 | F116: =100-E116 -> 100 | G116: =F116/100 -> 1 | I116: =H116/G116 -> 0
A117: FYV-010 | F117: =100-E117 -> 100 | G117: =F117/100 -> 1 | I117: =H117/G117 -> 0
A118: FYV-011 | F118: =100-E118 -> 100 | G118: =F118/100 -> 1 | I118: =H118/G118 -> 0
A119: FYV-012 | F119: =100-E119 -> 100 | G119: =F119/100 -> 1 | I119: =H119/G119 -> 0
... A207: FYV-100 | F207: =100-E207 -> 100 | G207: =F207/100 -> 1 | I207: =H207/G207 -> 0
A209: Almacén de cárnicos (res, cerdo, aves, pescados, mariscos, animales de caza, etc.)
A210: Código | B210: Producto | C210: Marca o proveedor | D210: Unidad | E210: % Merma | F210: Utilizable | G210: Peso neto | H210: Costo bruto | I210: Costo neto
B211: Res
A212: RES-001 | F212: =100-E212 -> 100 | G212: =F212/100 -> 1 | I212: =H212/G212 -> 0
A213: RES-002 | F213: =100-E213 -> 100 | G213: =F213/100 -> 1 | I213: =H213/G213 -> 0
...

Sheet SUBRECETAS Y GUARNICIONES
A1: NOMBRE DEL ESTABLECIMIENTO
A2: SUB-RECETAS | L2: GUARNICIONES
A4: NOMBRE: | F4: FECHA: | L4: NOMBRE: | Q4: FECHA: | R4: =$G$4 | W4: NOMBRE: | AB4: FECHA: | AC4: =$G$4
A5: CÓDIGO DE RECETA: | B5: sub001 | D5: PORCIONES: | E5: 1 | L5: CÓDIGO DE RECETA: | M5: Gua001 | O5: PORCIONES: | W5: CÓDIGO DE RECETA: | Z5: PORCIONES:
A6: CÓDIGO | B6: INGREDIENTES | D6: CANTIDAD | E6: UNIDAD | F6: EQUIPO Y UTENSILIOS | I6: COSTO NETO | J6: IMPORTE | L6: CÓDIGO | M6: INGREDIENTES | O6: CANTIDAD | P6: UNIDAD | Q6: EQUIPO Y UTENSILIOS | T6: COSTO NETO | U6: IMPORTE | W6: CÓDIGO | X6: INGREDIENTES | Z6: CANTIDAD | AA6: UNIDAD | AB6: EQUIPO Y UTENSILIOS | AE6: COSTO NETO | AF6: IMPORTE
A7: =VLOOKUP(B7,Base!$A$3:$F$994, 6, false) -> 0 | B7: . | E7: =VLOOKUP(B7,Base!$A$3:$F$994, 2, false) -> . | I7: =VLOOKUP(B7,Base!$A$3:$F$994, 5, false) -> 0 | J7: =I7*D7 -> 0 | L7: =VLOOKUP(M7,Base!$A$3:$F$994, 6, false) -> 0 | M7: . | P7: =VLOOKUP(M7,Base!$A$3:$F$994, 2, false) -> . | T7: =VLOOKUP(M7,Base!$A$3:$F$994, 5, false) -> 0 | U7: =T7*O7 -> 0 | W7: =VLOOKUP(X7,Base!$A$3:$F$994, 6, false) -> 0 | X7: . | AA7: =VLOOKUP(X7,Base!$A$3:$F$994, 2, false) -> . | AE7: =VLOOKUP(X7,Base!$A$3:$F$994, 5, false) -> 0 | AF7: =AE7*Z7 -> 0
A8: =VLOOKUP(B8,Base!$A$3:$F$994, 6, false) -> 0 | B8: . | E8: =VLOOKUP(B8,Base!$A$3:$F$994, 2, false) -> . | I8: =VLOOKUP(B8,Base!$A$3:$F$994, 5, false) -> 0 | J8: =I8*D8 -> 0 | L8: =VLOOKUP(M8,Base!$A$3:$F$994, 6, false) -> 0 | M8: . | P8: =VLOOKUP(M8,Base!$A$3:$F$994, 2, false) -> . | T8: =VLOOKUP(M8,Base!$A$3:$F$994, 5, false) -> 0 | U8: =T8*O8 -> 0 | W8: =VLOOKUP(X8,Base!$A$3:$F$994, 6, false) -> 0 | X8: . | AA8: =VLOOKUP(X8,Base!$A$3:$F$994, 2, false) -> . | AE8: =VLOOKUP(X8,Base!$A$3:$F$994, 5, false) -> 0 | AF8: =AE8*Z8 -> 0
A9: =VLOOKUP(B9,Base!$A$3:$F$994, 6, false) -> 0 | B9: . | E9: =VLOOKUP(B9,Base!$A$3:$F$994, 2, false) -> . | I9: =VLOOKUP(B9,Base!$A$3:$F$994, 5, false) -> 0 | J9: =I9*D9 -> 0 | L9: =VLOOKUP(M9,Base!$A$3:$F$994, 6, false) -> 0 | M9: . | P9: =VLOOKUP(M9,Base!$A$3:$F$994, 2, false) -> . | T9: =VLOOKUP(M9,Base!$A$3:$F$994, 5, false) -> 0 | U9: =T9*O9 -> 0 | W9: =VLOOKUP(X9,Base!$A$3:$F$994, 6, false) -> 0 | X9: . | AA9: =VLOOKUP(X9,Base!$A$3:$F$994, 2, false) -> . | AE9: =VLOOKUP(X9,Base!$A$3:$F$994, 5, false) -> 0 | AF9: =AE9*Z9 -> 0
A10: =VLOOKUP(B10,Base!$A$3:$F$994, 6, false) -> 0 | B10: . | E10: =VLOOKUP(B10,Base!$A$3:$F$994, 2, false) -> . | I10: =VLOOKUP(B10,Base!$A$3:$F$994, 5, false) -> 0 | J10: =I10*D10 -> 0 | L10: =VLOOKUP(M10,Base!$A$3:$F$994, 6, false) -> 0 | M10: . | P10: =VLOOKUP(M10,Base!$A$3:$F$994, 2, false) -> . | T10: =VLOOKUP(M10,Base!$A$3:$F$994, 5, false) -> 0 | U10: =T10*O10 -> 0 | W10: =VLOOKUP(X10,Base!$A$3:$F$994, 6, false) -> 0 | X10: . | AA10: =VLOOKUP(X10,Base!$A$3:$F$994, 2, false) -> . | AE10: =VLOOKUP(X10,Base!$A$3:$F$994, 5, false) -> 0 | AF10: =AE10*Z10 -> 0
A11: =VLOOKUP(B11,Base!$A$3:$F$994, 6, false) -> 0 | B11: . | E11: =VLOOKUP(B11,Base!$A$3:$F$994, 2, false) -> . | I11: =VLOOKUP(B11,Base!$A$3:$F$994, 5, false) -> 0 | J11: =I11*D11 -> 0 | L11: =VLOOKUP(M11,Base!$A$3:$F$994, 6, false) -> 0 | M11: . | P11: =VLOOKUP(M11,Base!$A$3:$F$994, 2, false) -> . | T11: =VLOOKUP(M11,Base!$A$3:$F$994, 5, false) -> 0 | U11: =T11*O11 -> 0 | W11: =VLOOKUP(X11,Base!$A$3:$F$994, 6, false) -> 0 | X11: . | AA11: =VLOOKUP(X11,Base!$A$3:$F$994, 2, false) -> . | AE11: =VLOOKUP(X11,Base!$A$3:$F$994, 5, false) -> 0 | AF11: =AE11*Z11 -> 0
A12: =VLOOKUP(B12,Base!$A$3:$F$994, 6, false) -> 0 | B12: . | E12: =VLOOKUP(B12,Base!$A$3:$F$994, 2, false) -> . | I12: =VLOOKUP(B12,Base!$A$3:$F$994, 5, false) -> 0 | J12: =I12*D12 -> 0 | L12: =VLOOKUP(M12,Base!$A$3:$F$994, 6, false) -> 0 | M12: . | P12: =VLOOKUP(M12,Base!$A$3:$F$994, 2, false) -> . | T12: =VLOOKUP(M12,Base!$A$3:$F$994, 5, false) -> 0 | U12: =T12*O12 -> 0 | W12: =VLOOKUP(X12,Base!$A$3:$F$994, 6, false) -> 0 | X12: . | AA12: =VLOOKUP(X12,Base!$A$3:$F$994, 2, false) -> . | AE12: =VLOOKUP(X12,Base!$A$3:$F$994, 5, false) -> 0 | AF12: =AE12*Z12 -> 0
A13: =VLOOKUP(B13,Base!$A$3:$F$994, 6, false) -> 0 | B13: . | E13: =VLOOKUP(B13,Base!$A$3:$F$994, 2, false) -> . | I13: =VLOOKUP(B13,Base!$A$3:$F$994, 5, false) -> 0 | J13: =I13*D13 -> 0 | L13: =VLOOKUP(M13,Base!$A$3:$F$994, 6, false) -> 0 | M13: . | P13: =VLOOKUP(M13,Base!$A$3:$F$994, 2, false) -> . | T13: =VLOOKUP(M13,Base!$A$3:$F$994, 5, false) -> 0 | U13: =T13*O13 -> 0 | W13: =VLOOKUP(X13,Base!$A$3:$F$994, 6, false) -> 0 | X13: . | AA13: =VLOOKUP(X13,Base!$A$3:$F$994, 2, false) -> . | AE13: =VLOOKUP(X13,Base!$A$3:$F$994, 5, false) -> 0 | AF13: =AE13*Z13 -> 0
A14: =VLOOKUP(B14,Base!$A$3:$F$994, 6, false) -> 0 | B14: . | E14: =VLOOKUP(B14,Base!$A$3:$F$994, 2, false) -> . | I14: =VLOOKUP(B14,Base!$A$3:$F$994, 5, false) -> 0 | J14: =I14*D14 -> 0 | L14: =VLOOKUP(M14,Base!$A$3:$F$994, 6, false) -> 0 | M14: . | P14: =VLOOKUP(M14,Base!$A$3:$F$994, 2, false) -> . | T14: =VLOOKUP(M14,Base!$A$3:$F$994, 5, false) -> 0 | U14: =T14*O14 -> 0 | W14: =VLOOKUP(X14,Base!$A$3:$F$994, 6, false) -> 0 | X14: . | AA14: =VLOOKUP(X14,Base!$A$3:$F$994, 2, false) -> . | AE14: =VLOOKUP(X14,Base!$A$3:$F$994, 5, false) -> 0 | AF14: =AE14*Z14 -> 0
A15: =VLOOKUP(B15,Base!$A$3:$F$994, 6, false) -> 0 | B15: . | E15: =VLOOKUP(B15,Base!$A$3:$F$994, 2, false) -> . | I15: =VLOOKUP(B15,Base!$A$3:$F$994, 5, false) -> 0 | J15: =I15*D15 -> 0 | L15: =VLOOKUP(M15,Base!$A$3:$F$994, 6, false) -> 0 | M15: . | P15: =VLOOKUP(M15,Base!$A$3:$F$994, 2, false) -> . | T15: =VLOOKUP(M15,Base!$A$3:$F$994, 5, false) -> 0 | U15: =T15*O15 -> 0 | W15: =VLOOKUP(X15,Base!$A$3:$F$994, 6, false) -> 0 | X15: . | AA15: =VLOOKUP(X15,Base!$A$3:$F$994, 2, false) -> . | AE15: =VLOOKUP(X15,Base!$A$3:$F$994, 5, false) -> 0 | AF15: =AE15*Z15 -> 0
A16: =VLOOKUP(B16,Base!$A$3:$F$994, 6, false) -> 0 | B16: . | E16: =VLOOKUP(B16,Base!$A$3:$F$994, 2, false) -> . | I16: =VLOOKUP(B16,Base!$A$3:$F$994, 5, false) -> 0 | J16: =I16*D16 -> 0 | L16: =VLOOKUP(M16,Base!$A$3:$F$994, 6, false) -> 0 | M16: . | P16: =VLOOKUP(M16,Base!$A$3:$F$994, 2, false) -> . | T16: =VLOOKUP(M16,Base!$A$3:$F$994, 5, false) -> 0 | U16: =T16*O16 -> 0 | W16: =VLOOKUP(X16,Base!$A$3:$F$994, 6, false) -> 0 | X16: . | AA16: =VLOOKUP(X16,Base!$A$3:$F$994, 2, false) -> . | AE16: =VLOOKUP(X16,Base!$A$3:$F$994, 5, false) -> 0 | AF16: =AE16*Z16 -> 0
A17: =VLOOKUP(B17,Base!$A$3:$F$994, 6, false) -> 0 | B17: . | E17: =VLOOKUP(B17,Base!$A$3:$F$994, 2, false) -> . | F17: PREPARACIÒN | I17: =VLOOKUP(B17,Base!$A$3:$F$994, 5, false) -> 0 | J17: =I17*D17 -> 0 | L17: =VLOOKUP(M17,Base!$A$3:$F$994, 6, false) -> 0 | M17: . | P17: =VLOOKUP(M17,Base!$A$3:$F$994, 2, false) -> . | Q17: PREPARACIÒN | T17: =VLOOKUP(M17,Base!$A$3:$F$994, 5, false) -> 0 | U17: =T17*O17 -> 0 | W17: =VLOOKUP(X17,Base!$A$3:$F$994, 6, false) -> 0 | X17: . | AA17: =VLOOKUP(X17,Base!$A$3:$F$994, 2, false) -> . | AB17: PREPARACIÒN | AE17: =VLOOKUP(X17,Base!$A$3:$F$994, 5, false) -> 0 | AF17: =AE17*Z17 -> 0
A18: =VLOOKUP(B18,Base!$A$3:$F$994, 6, false) -> 0 | B18: . | E18: =VLOOKUP(B18,Base!$A$3:$F$994, 2, false) -> . | I18: =VLOOKUP(B18,Base!$A$3:$F$994, 5, false) -> 0 | J18: =I18*D18 -> 0 | L18: =VLOOKUP(M18,Base!$A$3:$F$994, 6, false) -> 0 | M18: . | P18: =VLOOKUP(M18,Base!$A$3:$F$994, 2, false) -> . | T18: =VLOOKUP(M18,Base!$A$3:$F$994, 5, false) -> 0 | U18: =T18*O18 -> 0 | W18: =VLOOKUP(X18,Base!$A$3:$F$994, 6, false) -> 0 | X18: . | AA18: =VLOOKUP(X18,Base!$A$3:$F$994, 2, false) -> . | AE18: =VLOOKUP(X18,Base!$A$3:$F$994, 5, false) -> 0 | AF18: =AE18*Z18 -> 0
A19: =VLOOKUP(B19,Base!$A$3:$F$994, 6, false) -> 0 | B19: . | E19: =VLOOKUP(B19,Base!$A$3:$F$994, 2, false) -> . | I19: =VLOOKUP(B19,Base!$A$3:$F$994, 5, false) -> 0 | J19: =I19*D19 -> 0 | L19: =VLOOKUP(M19,Base!$A$3:$F$994, 6, false) -> 0 | M19: . | P19: =VLOOKUP(M19,Base!$A$3:$F$994, 2, false) -> . | T19: =VLOOKUP(M19,Base!$A$3:$F$994, 5, false) -> 0 | U19: =T19*O19 -> 0 | W19: =VLOOKUP(X19,Base!$A$3:$F$994, 6, false) -> 0 | X19: . | AA19: =VLOOKUP(X19,Base!$A$3:$F$994, 2, false) -> . | AE19: =VLOOKUP(X19,Base!$A$3:$F$994, 5, false) -> 0 | AF19: =AE19*Z19 -> 0
A20: =VLOOKUP(B20,Base!$A$3:$F$994, 6, false) -> 0 | B20: . | E20: =VLOOKUP(B20,Base!$A$3:$F$994, 2, false) -> . | I20: =VLOOKUP(B20,Base!$A$3:$F$994, 5, false) -> 0 | J20: =I20*D20 -> 0 | L20: =VLOOKUP(M20,Base!$A$3:$F$994, 6, false) -> 0 | M20: . | P20: =VLOOKUP(M20,Base!$A$3:$F$994, 2, false) -> . | T20: =VLOOKUP(M20,Base!$A$3:$F$994, 5, false) -> 0 | U20: =T20*O20 -> 0 | W20: =VLOOKUP(X20,Base!$A$3:$F$994, 6, false) -> 0 | X20: . | AA20: =VLOOKUP(X20,Base!$A$3:$F$994, 2, false) -> . | AE20: =VLOOKUP(X20,Base!$A$3:$F$994, 5, false) -> 0 | AF20: =AE20*Z20 -> 0
A21: =VLOOKUP(B21,Base!$A$3:$F$994, 6, false) -> 0 | B21: . | E21: =VLOOKUP(B21,Base!$A$3:$F$994, 2, false) -> . | I21: =VLOOKUP(B21,Base!$A$3:$F$994, 5, false) -> 0 | J21: =I21*D21 -> 0 | L21: =VLOOKUP(M21,Base!$A$3:$F$994, 6, false) -> 0 | M21: . | P21: =VLOOKUP(M21,Base!$A$3:$F$994, 2, false) -> . | T21: =VLOOKUP(M21,Base!$A$3:$F$994, 5, false) -> 0 | U21: =T21*O21 -> 0 | W21: =VLOOKUP(X21,Base!$A$3:$F$994, 6, false) -> 0 | X21: . | AA21: =VLOOKUP(X21,Base!$A$3:$F$994, 2, false) -> . | AE21: =VLOOKUP(X21,Base!$A$3:$F$994, 5, false) -> 0 | AF21: =AE21*Z21 -> 0
A22: =VLOOKUP(B22,Base!$A$3:$F$994, 6, false) -> 0 | B22: . | E22: =VLOOKUP(B22,Base!$A$3:$F$994, 2, false) -> . | I22: =VLOOKUP(B22,Base!$A$3:$F$994, 5, false) -> 0 | J22: =I22*D22 -> 0 | L22: =VLOOKUP(M22,Base!$A$3:$F$994, 6, false) -> 0 | M22: . | P22: =VLOOKUP(M22,Base!$A$3:$F$994, 2, false) -> . | T22: =VLOOKUP(M22,Base!$A$3:$F$994, 5, false) -> 0 | U22: =T22*O22 -> 0 | W22: =VLOOKUP(X22,Base!$A$3:$F$994, 6, false) -> 0 | X22: . | AA22: =VLOOKUP(X22,Base!$A$3:$F$994, 2, false) -> . | AE22: =VLOOKUP(X22,Base!$A$3:$F$994, 5, false) -> 0 | AF22: =AE22*Z22 -> 0
A23: =VLOOKUP(B23,Base!$A$3:$F$994, 6, false) -> 0 | B23: . | E23: =VLOOKUP(B23,Base!$A$3:$F$994, 2, false) -> . | I23: =VLOOKUP(B23,Base!$A$3:$F$994, 5, false) -> 0 | J23: =I23*D23 -> 0 | L23: =VLOOKUP(M23,Base!$A$3:$F$994, 6, false) -> 0 | M23: . | P23: =VLOOKUP(M23,Base!$A$3:$F$994, 2, false) -> . | T23: =VLOOKUP(M23,Base!$A$3:$F$994, 5, false) -> 0 | U23: =T23*O23 -> 0 | W23: =VLOOKUP(X23,Base!$A$3:$F$994, 6, false) -> 0 | X23: . | AA23: =VLOOKUP(X23,Base!$A$3:$F$994, 2, false) -> . | AE23: =VLOOKUP(X23,Base!$A$3:$F$994, 5, false) -> 0 | AF23: =AE23*Z23 -> 0
A24: =VLOOKUP(B24,Base!$A$3:$F$994, 6, false) -> 0 | B24: . | E24: =VLOOKUP(B24,Base!$A$3:$F$994, 2, false) -> . | I24: =VLOOKUP(B24,Base!$A$3:$F$994, 5, false) -> 0 | J24: =I24*D24 -> 0 | L24: =VLOOKUP(M24,Base!$A$3:$F$994, 6, false) -> 0 | M24: . | P24: =VLOOKUP(M24,Base!$A$3:$F$994, 2, false) -> . | T24: =VLOOKUP(M24,Base!$A$3:$F$994, 5, false) -> 0 | U24: =T24*O24 -> 0 | W24: =VLOOKUP(X24,Base!$A$3:$F$994, 6, false) -> 0 | X24: . | AA24: =VLOOKUP(X24,Base!$A$3:$F$994, 2, false) -> . | AE24: =VLOOKUP(X24,Base!$A$3:$F$994, 5, false) -> 0 | AF24: =AE24*Z24 -> 0
A25: ELABORACION | I25: TOTAL DE MP: | J25: =SUM(J7:J24) -> 0 | L25: ELABORACIÒN | T25: TOTAL DE MP: | U25: =SUM(U7:U24) -> 0 | W25: ELABORACIÒN | AE25: TOTAL DE MP: | AF25: =SUM(AF7:AF24) -> 0
I26: TOTAL P/P: | J26: =J25/E5 -> 0 | T26: TOTAL P/P: | U26: =U25/P5 -> #DIV/0! | AE26: TOTAL P/P: | AF26: =AF25/AA5 -> #DIV/0!
I27: IMPREVISTO: | J27: 0.05 | T27: IMPREVISTO: | U27: 0.05 | AE27: IMPREVISTO: | AF27: 0.05
I28: TOTAL DE COSTO: | J28: =J26+(J26*J27) -> 0 | T28: TOTAL DE COSTO: | U28: =U26+(U26*U27) -> #DIV/0! | AE28: TOTAL DE COSTO: | AF28: =AF26+(AF26*AF27) -> #DIV/0!
A34: MONTAJE | L34: MONTAJE | W34: MONTAJE
A38: OBSERVACIONES | L38: OBSERVACIONES | W38: OBSERVACIONES
A47: NOMBRE: | F47: FECHA: | G47: =$G$4 | L47: NOMBRE: | Q47: FECHA: | R47: =$G$4 | W47: NOMBRE: | AB47: FECHA: | AC47: =$G$4
A48: CÓDIGO DE RECETA: | D48: PORCIONES: | L48: CÓDIGO DE RECETA: | O48: PORCIONES: | W48: CÓDIGO DE RECETA: | Z48: PORCIONES:
A49: CÓDIGO | B49: INGREDIENTES | D49: CANTIDAD | E49: UNIDAD | F49: EQUIPO Y UTENSILIOS | I49: COSTO NETO | J49: IMPORTE | L49: CÓDIGO | M49: INGREDIENTES | O49: CANTIDAD | P49: UNIDAD | Q49: EQUIPO Y UTENSILIOS | T49: COSTO NETO | U49: IMPORTE | W49: CÓDIGO | X49: INGREDIENTES | Z49: CANTIDAD | AA49: UNIDAD | AB49: EQUIPO Y UTENSILIOS | AE49: COSTO NETO | AF49: IMPORTE
A50: =VLOOKUP(B50,Base!$A$3:$F$994, 6, false) -> 0 | B50: . | E50: =VLOOKUP(B50,Base!$A$3:$F$994, 2, false) -> . | I50: =VLOOKUP(B50,Base!$A$3:$F$994, 5, false) -> 0 | J50: =I50*D50 -> 0 | L50: =VLOOKUP(M50,Base!$A$3:$F$994, 6, false) -> 0 | M50: . | P50: =VLOOKUP(M50,Base!$A$3:$F$994, 2, false) -> . | T50: =VLOOKUP(M50,Base!$A$3:$F$994, 5, false) -> 0 | U50: =T50*O50 -> 0 | W50: =VLOOKUP(X50,Base!$A$3:$F$994, 6, false) -> 0 | X50: . | AA50: =VLOOKUP(X50,Base!$A$3:$F$994, 2, false) -> . | AE50: =VLOOKUP(X50,Base!$A$3:$F$994, 5, false) -> 0 | AF50: =AE50*Z50 -> 0
A51: =VLOOKUP(B51,Base!$A$3:$F$994, 6, false) -> 0 | B51: . | E51: =VLOOKUP(B51,Base!$A$3:$F$994, 2, false) -> . | I51: =VLOOKUP(B51,Base!$A$3:$F$994, 5, false) -> 0 | J51: =I51*D51 -> 0 | L51: =VLOOKUP(M51,Base!$A$3:$F$994, 6, false) -> 0 | M51: . | P51: =VLOOKUP(M51,Base!$A$3:$F$994, 2, false) -> . | T51: =VLOOKUP(M51,Base!$A$3:$F$994, 5, false) -> 0 | U51: =T51*O51 -> 0 | W51: =VLOOKUP(X51,Base!$A$3:$F$994, 6, false) -> 0 | X51: . | AA51: =VLOOKUP(X51,Base!$A$3:$F$994, 2, false) -> . | AE51: =VLOOKUP(X51,Base!$A$3:$F$994, 5, false) -> 0 | AF51: =AE51*Z51 -> 0
A52: =VLOOKUP(B52,Base!$A$3:$F$994, 6, false) -> 0 | B52: . | E52: =VLOOKUP(B52,Base!$A$3:$F$994, 2, false) -> . | I52: =VLOOKUP(B52,Base!$A$3:$F$994, 5, false) -> 0 | J52: =I52*D52 -> 0 | L52: =VLOOKUP(M52,Base!$A$3:$F$994, 6, false) -> 0 | M52: . | P52: =VLOOKUP(M52,Base!$A$3:$F$994, 2, false) -> . | T52: =VLOOKUP(M52,Base!$A$3:$F$994, 5, false) -> 0 | U52: =T52*O52 -> 0 | W52: =VLOOKUP(X52,Base!$A$3:$F$994, 6, false) -> 0 | X52: . | AA52: =VLOOKUP(X52,Base!$A$3:$F$994, 2, false) -> . | AE52: =VLOOKUP(X52,Base!$A$3:$F$994, 5, false) -> 0 | AF52: =AE52*Z52 -> 0
A53: =VLOOKUP(B53,Base!$A$3:$F$994, 6, false) -> 0 | B53: . | E53: =VLOOKUP(B53,Base!$A$3:$F$994, 2, false) -> . | I53: =VLOOKUP(B53,Base!$A$3:$F$994, 5, false) -> 0 | J53: =I53*D53 -> 0 | L53: =VLOOKUP(M53,Base!$A$3:$F$994, 6, false) -> 0 | M53: . | P53: =VLOOKUP(M53,Base!$A$3:$F$994, 2, false) -> . | T53: =VLOOKUP(M53,Base!$A$3:$F$994, 5, false) -> 0 | U53: =T53*O53 -> 0 | W53: =VLOOKUP(X53,Base!$A$3:$F$994, 6, false) -> 0 | X53: . | AA53: =VLOOKUP(X53,Base!$A$3:$F$994, 2, false) -> . | AE53: =VLOOKUP(X53,Base!$A$3:$F$994, 5, false) -> 0 | AF53: =AE53*Z53 -> 0
A54: =VLOOKUP(B54,Base!$A$3:$F$994, 6, false) -> 0 | B54: . | E54: =VLOOKUP(B54,Base!$A$3:$F$994, 2, false) -> . | I54: =VLOOKUP(B54,Base!$A$3:$F$994, 5, false) -> 0 | J54: =I54*D54 -> 0 | L54: =VLOOKUP(M54,Base!$A$3:$F$994, 6, false) -> 0 | M54: . | P54: =VLOOKUP(M54,Base!$A$3:$F$994, 2, false) -> . | T54: =VLOOKUP(M54,Base!$A$3:$F$994, 5, false) -> 0 | U54: =T54*O54 -> 0 | W54: =VLOOKUP(X54,Base!$A$3:$F$994, 6, false) -> 0 | X54: . | AA54: =VLOOKUP(X54,Base!$A$3:$F$994, 2, false) -> . | AE54: =VLOOKUP(X54,Base!$A$3:$F$994, 5, false) -> 0 | AF54: =AE54*Z54 -> 0
A55: =VLOOKUP(B55,Base!$A$3:$F$994, 6, false) -> 0 | B55: . | E55: =VLOOKUP(B55,Base!$A$3:$F$994, 2, false) -> . | I55: =VLOOKUP(B55,Base!$A$3:$F$994, 5, false) -> 0 | J55: =I55*D55 -> 0 | L55: =VLOOKUP(M55,Base!$A$3:$F$994, 6, false) -> 0 | M55: . | P55: =VLOOKUP(M55,Base!$A$3:$F$994, 2, false) -> . | T55: =VLOOKUP(M55,Base!$A$3:$F$994, 5, false) -> 0 | U55: =T55*O55 -> 0 | W55: =VLOOKUP(X55,Base!$A$3:$F$994, 6, false) -> 0 | X55: . | AA55: =VLOOKUP(X55,Base!$A$3:$F$994, 2, false) -> . | AE55: =VLOOKUP(X55,Base!$A$3:$F$994, 5, false) -> 0 | AF55: =AE55*Z55 -> 0
A56: =VLOOKUP(B56,Base!$A$3:$F$994, 6, false) -> 0 | B56: . | E56: =VLOOKUP(B56,Base!$A$3:$F$994, 2, false) -> . | I56: =VLOOKUP(B56,Base!$A$3:$F$994, 5, false) -> 0 | J56: =I56*D56 -> 0 | L56: =VLOOKUP(M56,Base!$A$3:$F$994, 6, false) -> 0 | M56: . | P56: =VLOOKUP(M56,Base!$A$3:$F$994, 2, false) -> . | T56: =VLOOKUP(M56,Base!$A$3:$F$994, 5, false) -> 0 | U56: =T56*O56 -> 0 | W56: =VLOOKUP(X56,Base!$A$3:$F$994, 6, false) -> 0 | X56: . | AA56: =VLOOKUP(X56,Base!$A$3:$F$994, 2, false) -> . | AE56: =VLOOKUP(X56,Base!$A$3:$F$994, 5, false) -> 0 | AF56: =AE56*Z56 -> 0
A57: =VLOOKUP(B57,Base!$A$3:$F$994, 6, false) -> 0 | B57: . | E57: =VLOOKUP(B57,Base!$A$3:$F$994, 2, false) -> . | I57: =VLOOKUP(B57,Base!$A$3:$F$994, 5, false) -> 0 | J57: =I57*D57 -> 0 | L57: =VLOOKUP(M57,Base!$A$3:$F$994, 6, false) -> 0 | M57: . | P57: =VLOOKUP(M57,Base!$A$3:$F$994, 2, false) -> . | T57: =VLOOKUP(M57,Base!$A$3:$F$994, 5, false) -> 0 | U57: =T57*O57 -> 0 | W57: =VLOOKUP(X57,Base!$A$3:$F$994, 6, false) -> 0 | X57: . | AA57: =VLOOKUP(X57,Base!$A$3:$F$994, 2, false) -> . | AE57: =VLOOKUP(X57,Base!$A$3:$F$994, 5, false) -> 0 | AF57: =AE57*Z57 -> 0
...

Sheet CONCENTRADO DE SUB Y GUA
A1: NOMBRE DEL ESTABLECIMIENTO
B3: SUB-RECETAS | G3: GUARNICIONES
B4: Código | C4: Nombre/Producto | D4: Unidad | E4: Total de costo | G4: Código | H4: Nombre/Producto | I4: Unidad | J4: Total de costo
B5: 1 | G5: 1
B6: 2 | G6: 2
B7: 3 | G7: 3
B8: 4 | G8: 4
B9: 5 | G9: 5
B10: 6 | G10: 6
B11: 7 | G11: 7
B12: 8 | G12: 8
B13: 9 | G13: 9
B14: 10 | G14: 10
B15: 11 | G15: 11
B16: 12 | G16: 12
... B34: 30 | G34: 30

Sheet REC ALIMENTOS
A1: NOMBRE DEL ESTABLECIMIENTO
A2: PRIMER TIEMPO | L2: SEGUNDO TIEMPO | W2: TERCER TIEMPO | AH2: CUARTO TIEMPO | AS2: QUINTO TIEMPO | BD2: SEXTO TIEMPO
I3: IMPUESTO | J3: 0.16 | T3: IMPUESTO: | U3: =$J$3 -> 0.16 | AE3: IMPUESTO: | AF3: =$J$3 -> 0.16 | AP3: IMPUESTO: | AQ3: =$J$3 -> 0.16 | BA3: IMPUESTO: | BB3: =$J$3 -> 0.16 | BL3: IMPUESTO: | BM3: =$J$3 -> 0.16
A4: NOMBRE: | F4: FECHA: | G4: 42399 | I4: FACTOR DE VENTA | J4: % DE COSTO | L4: NOMBRE: | Q4: FECHA: | R4: =$G$4 -> 42399 | T4: FACTOR DE VENTA | U4: % DE COSTO | W4: NOMBRE: | AB4: FECHA: | AC4: =$G$4 -> 42399 | AE4: FACTOR DE VENTA | AF4: % DE COSTO | AH4: NOMBRE: | AM4: FECHA: | AN4: =$G$4 -> 42399 | AP4: FACTOR DE VENTA | AQ4: % DE COSTO | AS4: NOMBRE: | AX4: FECHA: | AY4: =$G$4 -> 42399 | BA4: FACTOR DE VENTA | BB4: % DE COSTO | BD4: NOMBRE: | BI4: FECHA: | BJ4: =$G$4 -> 42399 | BL4: FACTOR DE VENTA | BM4: % DE COSTO
A5: CÓDIGO DE RECETA: | D5: PORCIONES: | I5: =1/J5 -> 3.3333333 | J5: 0.3 | L5: CÓDIGO DE RECETA: | O5: PORCIONES: | P5: 10 | T5: =1/U5 -> 3.3333333 | U5: =$J$5 -> 0.3 | W5: CÓDIGO DE RECETA: | Z5: PORCIONES: | AA5: 10 | AE5: =1/AF5 -> 3.3333333 | AF5: =$J$5 -> 0.3 | AH5: CÓDIGO DE RECETA: | AK5: PORCIONES: | AL5: 10 | AP5: =1/AQ5 -> 3.3333333 | AQ5: =$J$5 -> 0.3 | AS5: CÓDIGO DE RECETA: | AV5: PORCIONES: | AW5: 10 | BA5: =1/BB5 -> 3.3333333 | BB5: =$J$5 -> 0.3 | BD5: CÓDIGO DE RECETA: | BG5: PORCIONES: | BH5: 10 | BL5: =1/BM5 -> 3.3333333 | BM5: =$J$5 -> 0.3
A6: CÓDIGO | B6: INGREDIENTES | D6: CANTIDAD | E6: UNIDAD | F6: EQUIPO Y UTENSILIOS | I6: COSTO NETO | J6: IMPORTE | L6: CÓDIGO | M6: INGREDIENTES | O6: CANTIDAD | P6: UNIDAD | Q6: EQUIPO Y UTENSILIOS | T6: COSTO NETO | U6: IMPORTE | W6: CÓDIGO | X6: INGREDIENTES | Z6: CANTIDAD | AA6: UNIDAD | AB6: EQUIPO Y UTENSILIOS | AE6: COSTO NETO | AF6: IMPORTE | AH6: CÓDIGO | AI6: INGREDIENTES | AK6: CANTIDAD | AL6: UNIDAD | AM6: EQUIPO Y UTENSILIOS | AP6: COSTO NETO | AQ6: IMPORTE | AS6: CÓDIGO | AT6: INGREDIENTES | AV6: CANTIDAD | AW6: UNIDAD | AX6: EQUIPO Y UTENSILIOS | BA6: COSTO NETO | BB6: IMPORTE | BD6: CÓDIGO | BE6: INGREDIENTES | BG6: CANTIDAD | BH6: UNIDAD | BI6: EQUIPO Y UTENSILIOS | BL6: COSTO NETO | BM6: IMPORTE
A7: =VLOOKUP(B7,Base!$A$3:$F$994, 6, false) -> #N/A | B7: Azucar | D7: 0.200 | E7: =VLOOKUP(B7,Base!$A$3:$F$994, 2, false) -> #N/A | F7: Cuchara | I7: =VLOOKUP(B7,Base!$A$3:$F$994, 5, false) -> #N/A | J7: =I7*D7 -> #N/A | L7: =VLOOKUP(M7,Base!$A$3:$F$994, 6, false) -> 0 | M7: . | P7: =VLOOKUP(M7,Base!$A$3:$F$994, 2, false) -> . | T7: =VLOOKUP(M7,Base!$A$3:$F$994, 5, false) -> 0 | U7: =T7*O7 -> 0 | W7: =VLOOKUP(X7,Base!$A$3:$F$994, 6, false) -> 0 | X7: . | AA7: =VLOOKUP(X7,Base!$A$3:$F$994, 2, false) -> . | AE7: =VLOOKUP(X7,Base!$A$3:$F$994, 5, false) -> 0 | AF7: =AE7*Z7 -> 0 | AH7: =VLOOKUP(AI7,Base!$A$3:$F$994, 6, false) -> 0 | AI7: . | AL7: =VLOOKUP(AI7,Base!$A$3:$F$994, 2, false) -> . | AP7: =VLOOKUP(AI7,Base!$A$3:$F$994, 5, false) -> 0 | AQ7: =AP7*AK7 -> 0 | AS7: =VLOOKUP(AT7,Base!$A$3:$F$994, 6, false) -> 0 | AT7: . | AW7: =VLOOKUP(AT7,Base!$A$3:$F$994, 2, false) -> . | BA7: =VLOOKUP(AT7,Base!$A$3:$F$994, 5, false) -> 0 | BB7: =BA7*AV7 -> 0 | BD7: =VLOOKUP(BE7,Base!$A$3:$F$994, 6, false) -> 0 | BE7: . | BH7: =VLOOKUP(BE7,Base!$A$3:$F$994, 2, false) -> . | BL7: =VLOOKUP(BE7,Base!$A$3:$F$994, 5, false) -> 0 | BM7: =BL7*BG7 -> 0
A8: =VLOOKUP(B8,Base!$A$3:$F$994, 6, false) -> 0 | B8: . | E8: =VLOOKUP(B8,Base!$A$3:$F$994, 2, false) -> . | F8: Cuchillo de chef | I8: =VLOOKUP(B8,Base!$A$3:$F$994, 5, false) -> 0 | J8: =I8*D8 -> 0 | L8: =VLOOKUP(M8,Base!$A$3:$F$994, 6, false) -> 0 | M8: . | P8: =VLOOKUP(M8,Base!$A$3:$F$994, 2, false) -> . | T8: =VLOOKUP(M8,Base!$A$3:$F$994, 5, false) -> 0 | U8: =T8*O8 -> 0 | W8: =VLOOKUP(X8,Base!$A$3:$F$994, 6, false) -> 0 | X8: . | AA8: =VLOOKUP(X8,Base!$A$3:$F$994, 2, false) -> . | AE8: =VLOOKUP(X8,Base!$A$3:$F$994, 5, false) -> 0 | AF8: =AE8*Z8 -> 0 | AH8: =VLOOKUP(AI8,Base!$A$3:$F$994, 6, false) -> 0 | AI8: . | AL8: =VLOOKUP(AI8,Base!$A$3:$F$994, 2, false) -> . | AP8: =VLOOKUP(AI8,Base!$A$3:$F$994, 5, false) -> 0 | AQ8: =AP8*AK8 -> 0 | AS8: =VLOOKUP(AT8,Base!$A$3:$F$994, 6, false) -> 0 | AT8: . | AW8: =VLOOKUP(AT8,Base!$A$3:$F$994, 2, false) -> . | BA8: =VLOOKUP(AT8,Base!$A$3:$F$994, 5, false) -> 0 | BB8: =BA8*AV8 -> 0 | BD8: =VLOOKUP(BE8,Base!$A$3:$F$994, 6, false) -> 0 | BE8: . | BH8: =VLOOKUP(BE8,Base!$A$3:$F$994, 2, false) -> . | BL8: =VLOOKUP(BE8,Base!$A$3:$F$994, 5, false) -> 0 | BM8: =BL8*BG8 -> 0
A9: =VLOOKUP(B9,Base!$A$3:$F$994, 6, false) -> 0 | B9: . | E9: =VLOOKUP(B9,Base!$A$3:$F$994, 2, false) -> . | F9: Olla | I9: =VLOOKUP(B9,Base!$A$3:$F$994, 5, false) -> 0 | J9: =I9*D9 -> 0 | L9: =VLOOKUP(M9,Base!$A$3:$F$994, 6, false) -> 0 | M9: . | O9: 0 | P9: =VLOOKUP(M9,Base!$A$3:$F$994, 2, false) -> . | T9: =VLOOKUP(M9,Base!$A$3:$F$994, 5, false) -> 0 | U9: =T9*O9 -> 0 | W9: =VLOOKUP(X9,Base!$A$3:$F$994, 6, false) -> 0 | X9: . | AA9: =VLOOKUP(X9,Base!$A$3:$F$994, 2, false) -> . | AE9: =VLOOKUP(X9,Base!$A$3:$F$994, 5, false) -> 0 | AF9: =AE9*Z9 -> 0 | AH9: =VLOOKUP(AI9,Base!$A$3:$F$994, 6, false) -> 0 | AI9: . | AL9: =VLOOKUP(AI9,Base!$A$3:$F$994, 2, false) -> . | AP9: =VLOOKUP(AI9,Base!$A$3:$F$994, 5, false) -> 0 | AQ9: =AP9*AK9 -> 0 | AS9: =VLOOKUP(AT9,Base!$A$3:$F$994, 6, false) -> 0 | AT9: . | AW9: =VLOOKUP(AT9,Base!$A$3:$F$994, 2, false) -> . | BA9: =VLOOKUP(AT9,Base!$A$3:$F$994, 5, false) -> 0 | BB9: =BA9*AV9 -> 0 | BD9: =VLOOKUP(BE9,Base!$A$3:$F$994, 6, false) -> 0 | BE9: . | BH9: =VLOOKUP(BE9,Base!$A$3:$F$994, 2, false) -> . | BL9: =VLOOKUP(BE9,Base!$A$3:$F$994, 5, false) -> 0 | BM9: =BL9*BG9 -> 0
A10: =VLOOKUP(B10,Base!$A$3:$F$994, 6, false) -> 0 | B10: . | E10: =VLOOKUP(B10,Base!$A$3:$F$994, 2, false) -> . | F10: Tabla para cortar verdura | I10: =VLOOKUP(B10,Base!$A$3:$F$994, 5, false) -> 0 | J10: =I10*D10 -> 0 | L10: =VLOOKUP(M10,Base!$A$3:$F$994, 6, false) -> 0 | M10: . | P10: =VLOOKUP(M10,Base!$A$3:$F$994, 2, false) -> . | T10: =VLOOKUP(M10,Base!$A$3:$F$994, 5, false) -> 0 | U10: =T10*O10 -> 0 | W10: =VLOOKUP(X10,Base!$A$3:$F$994, 6, false) -> 0 | X10: . | AA10: =VLOOKUP(X10,Base!$A$3:$F$994, 2, false) -> . | AE10: =VLOOKUP(X10,Base!$A$3:$F$994, 5, false) -> 0 | AF10: =AE10*Z10 -> 0 | AH10: =VLOOKUP(AI10,Base!$A$3:$F$994, 6, false) -> 0 | AI10: . | AL10: =VLOOKUP(AI10,Base!$A$3:$F$994, 2, false) -> . | AP10: =VLOOKUP(AI10,Base!$A$3:$F$994, 5, false) -> 0 | AQ10: =AP10*AK10 -> 0 | AS10: =VLOOKUP(AT10,Base!$A$3:$F$994, 6, false) -> 0 | AT10: . | AW10: =VLOOKUP(AT10,Base!$A$3:$F$994, 2, false) -> . | BA10: =VLOOKUP(AT10,Base!$A$3:$F$994, 5, false) -> 0 | BB10: =BA10*AV10 -> 0 | BD10: =VLOOKUP(BE10,Base!$A$3:$F$994, 6, false) -> 0 | BE10: . | BH10: =VLOOKUP(BE10,Base!$A$3:$F$994, 2, false) -> . | BL10: =VLOOKUP(BE10,Base!$A$3:$F$994, 5, false) -> 0 | BM10: =BL10*BG10 -> 0
A11: =VLOOKUP(B11,Base!$A$3:$F$994, 6, false) -> 0 | B11: . | E11: =VLOOKUP(B11,Base!$A$3:$F$994, 2, false) -> . | F11: Parrilla | I11: =VLOOKUP(B11,Base!$A$3:$F$994, 5, false) -> 0 | J11: =I11*D11 -> 0 | L11: =VLOOKUP(M11,Base!$A$3:$F$994, 6, false) -> 0 | M11: . | P11: =VLOOKUP(M11,Base!$A$3:$F$994, 2, false) -> . | T11: =VLOOKUP(M11,Base!$A$3:$F$994, 5, false) -> 0 | U11: =T11*O11 -> 0 | W11: =VLOOKUP(X11,Base!$A$3:$F$994, 6, false) -> 0 | X11: . | AA11: =VLOOKUP(X11,Base!$A$3:$F$994, 2, false) -> . | AE11: =VLOOKUP(X11,Base!$A$3:$F$994, 5, false) -> 0 | AF11: =AE11*Z11 -> 0 | AH11: =VLOOKUP(AI11,Base!$A$3:$F$994, 6, false) -> 0 | AI11: . | AL11: =VLOOKUP(AI11,Base!$A$3:$F$994, 2, false) -> . | AP11: =VLOOKUP(AI11,Base!$A$3:$F$994, 5, false) -> 0 | AQ11: =AP11*AK11 -> 0 | AS11: =VLOOKUP(AT11,Base!$A$3:$F$994, 6, false) -> 0 | AT11: . | AW11: =VLOOKUP(AT11,Base!$A$3:$F$994, 2, false) -> . | BA11: =VLOOKUP(AT11,Base!$A$3:$F$994, 5, false) -> 0 | BB11: =BA11*AV11 -> 0 | BD11: =VLOOKUP(BE11,Base!$A$3:$F$994, 6, false) -> 0 | BE11: . | BH11: =VLOOKUP(BE11,Base!$A$3:$F$994, 2, false) -> . | BL11: =VLOOKUP(BE11,Base!$A$3:$F$994, 5, false) -> 0 | BM11: =BL11*BG11 -> 0
A12: =VLOOKUP(B12,Base!$A$3:$F$994, 6, false) -> 0 | B12: . | E12: =VLOOKUP(B12,Base!$A$3:$F$994, 2, false) -> . | I12: =VLOOKUP(B12,Base!$A$3:$F$994, 5, false) -> 0 | J12: =I12*D12 -> 0 | L12: =VLOOKUP(M12,Base!$A$3:$F$994, 6, false) -> 0 | M12: . | P12: =VLOOKUP(M12,Base!$A$3:$F$994, 2, false) -> . | T12: =VLOOKUP(M12,Base!$A$3:$F$994, 5, false) -> 0 | U12: =T12*O12 -> 0 | W12: =VLOOKUP(X12,Base!$A$3:$F$994, 6, false) -> 0 | X12: . | AA12: =VLOOKUP(X12,Base!$A$3:$F$994, 2, false) -> . | AE12: =VLOOKUP(X12,Base!$A$3:$F$994, 5, false) -> 0 | AF12: =AE12*Z12 -> 0 | AH12: =VLOOKUP(AI12,Base!$A$3:$F$994, 6, false) -> 0 | AI12: . | AL12: =VLOOKUP(AI12,Base!$A$3:$F$994, 2, false) -> . | AP12: =VLOOKUP(AI12,Base!$A$3:$F$994, 5, false) -> 0 | AQ12: =AP12*AK12 -> 0 | AS12: =VLOOKUP(AT12,Base!$A$3:$F$994, 6, false) -> 0 | AT12: . | AW12: =VLOOKUP(AT12,Base!$A$3:$F$994, 2, false) -> . | BA12: =VLOOKUP(AT12,Base!$A$3:$F$994, 5, false) -> 0 | BB12: =BA12*AV12 -> 0 | BD12: =VLOOKUP(BE12,Base!$A$3:$F$994, 6, false) -> 0 | BE12: . | BH12: =VLOOKUP(BE12,Base!$A$3:$F$994, 2, false) -> . | BL12: =VLOOKUP(BE12,Base!$A$3:$F$994, 5, false) -> 0 | BM12: =BL12*BG12 -> 0
A13: =VLOOKUP(B13,Base!$A$3:$F$994, 6, false) -> 0 | B13: . | E13: =VLOOKUP(B13,Base!$A$3:$F$994, 2, false) -> . | I13: =VLOOKUP(B13,Base!$A$3:$F$994, 5, false) -> 0 | J13: =I13*D13 -> 0 | L13: =VLOOKUP(M13,Base!$A$3:$F$994, 6, false) -> 0 | M13: . | P13: =VLOOKUP(M13,Base!$A$3:$F$994, 2, false) -> . | T13: =VLOOKUP(M13,Base!$A$3:$F$994, 5, false) -> 0 | U13: =T13*O13 -> 0 | W13: =VLOOKUP(X13,Base!$A$3:$F$994, 6, false) -> 0 | X13: . | AA13: =VLOOKUP(X13,Base!$A$3:$F$994, 2, false) -> . | AE13: =VLOOKUP(X13,Base!$A$3:$F$994, 5, false) -> 0 | AF13: =AE13*Z13 -> 0 | AH13: =VLOOKUP(AI13,Base!$A$3:$F$994, 6, false) -> 0 | AI13: . | AL13: =VLOOKUP(AI13,Base!$A$3:$F$994, 2, false) -> . | AP13: =VLOOKUP(AI13,Base!$A$3:$F$994, 5, false) -> 0 | AQ13: =AP13*AK13 -> 0 | AS13: =VLOOKUP(AT13,Base!$A$3:$F$994, 6, false) -> 0 | AT13: . | AW13: =VLOOKUP(AT13,Base!$A$3:$F$994, 2, false) -> . | BA13: =VLOOKUP(AT13,Base!$A$3:$F$994, 5, false) -> 0 | BB13: =BA13*AV13 -> 0 | BD13: =VLOOKUP(BE13,Base!$A$3:$F$994, 6, false) -> 0 | BE13: . | BH13: =VLOOKUP(BE13,Base!$A$3:$F$994, 2, false) -> . | BL13: =VLOOKUP(BE13,Base!$A$3:$F$994, 5, false) -> 0 | BM13: =BL13*BG13 -> 0
A14: =VLOOKUP(B14,Base!$A$3:$F$994, 6, false) -> 0 | B14: . | E14: =VLOOKUP(B14,Base!$A$3:$F$994, 2, false) -> . | I14: =VLOOKUP(B14,Base!$A$3:$F$994, 5, false) -> 0 | J14: =I14*D14 -> 0 | L14: =VLOOKUP(M14,Base!$A$3:$F$994, 6, false) -> 0 | M14: . | P14: =VLOOKUP(M14,Base!$A$3:$F$994, 2, false) -> . | T14: =VLOOKUP(M14,Base!$A$3:$F$994, 5, false) -> 0 | U14: =T14*O14 -> 0 | W14: =VLOOKUP(X14,Base!$A$3:$F$994, 6, false) -> 0 | X14: . | AA14: =VLOOKUP(X14,Base!$A$3:$F$994, 2, false) -> . | AE14: =VLOOKUP(X14,Base!$A$3:$F$994, 5, false) -> 0 | AF14: =AE14*Z14 -> 0 | AH14: =VLOOKUP(AI14,Base!$A$3:$F$994, 6, false) -> 0 | AI14: . | AL14: =VLOOKUP(AI14,Base!$A$3:$F$994, 2, false) -> . | AP14: =VLOOKUP(AI14,Base!$A$3:$F$994, 5, false) -> 0 | AQ14: =AP14*AK14 -> 0 | AS14: =VLOOKUP(AT14,Base!$A$3:$F$994, 6, false) -> 0 | AT14: . | AW14: =VLOOKUP(AT14,Base!$A$3:$F$994, 2, false) -> . | BA14: =VLOOKUP(AT14,Base!$A$3:$F$994, 5, false) -> 0 | BB14: =BA14*AV14 -> 0 | BD14: =VLOOKUP(BE14,Base!$A$3:$F$994, 6, false) -> 0 | BE14: . | BH14: =VLOOKUP(BE14,Base!$A$3:$F$994, 2, false) -> . | BL14: =VLOOKUP(BE14,Base!$A$3:$F$994, 5, false) -> 0 | BM14: =BL14*BG14 -> 0
A15: =VLOOKUP(B15,Base!$A$3:$F$994, 6, false) -> 0 | B15: . | E15: =VLOOKUP(B15,Base!$A$3:$F$994, 2, false) -> . | I15: =VLOOKUP(B15,Base!$A$3:$F$994, 5, false) -> 0 | J15: =I15*D15 -> 0 | L15: =VLOOKUP(M15,Base!$A$3:$F$994, 6, false) -> 0 | M15: . | P15: =VLOOKUP(M15,Base!$A$3:$F$994, 2, false) -> . | T15: =VLOOKUP(M15,Base!$A$3:$F$994, 5, false) -> 0 | U15: =T15*O15 -> 0 | W15: =VLOOKUP(X15,Base!$A$3:$F$994, 6, false) -> 0 | X15: . | AA15: =VLOOKUP(X15,Base!$A$3:$F$994, 2, false) -> . | AE15: =VLOOKUP(X15,Base!$A$3:$F$994, 5, false) -> 0 | AF15: =AE15*Z15 -> 0 | AH15: =VLOOKUP(AI15,Base!$A$3:$F$994, 6, false) -> 0 | AI15: . | AL15: =VLOOKUP(AI15,Base!$A$3:$F$994, 2, false) -> . | AP15: =VLOOKUP(AI15,Base!$A$3:$F$994, 5, false) -> 0 | AQ15: =AP15*AK15 -> 0 | AS15: =VLOOKUP(AT15,Base!$A$3:$F$994, 6, false) -> 0 | AT15: . | AW15: =VLOOKUP(AT15,Base!$A$3:$F$994, 2, false) -> . | BA15: =VLOOKUP(AT15,Base!$A$3:$F$994, 5, false) -> 0 | BB15: =BA15*AV15 -> 0 | BD15: =VLOOKUP(BE15,Base!$A$3:$F$994, 6, false) -> 0 | BE15: . | BH15: =VLOOKUP(BE15,Base!$A$3:$F$994, 2, false) -> . | BL15: =VLOOKUP(BE15,Base!$A$3:$F$994, 5, false) -> 0 | BM15: =BL15*BG15 -> 0
A16: =VLOOKUP(B16,Base!$A$3:$F$994, 6, false) -> 0 | B16: . | E16: =VLOOKUP(B16,Base!$A$3:$F$994, 2, false) -> . | I16: =VLOOKUP(B16,Base!$A$3:$F$994, 5, false) -> 0 | J16: =I16*D16 -> 0 | L16: =VLOOKUP(M16,Base!$A$3:$F$994, 6, false) -> 0 | M16: . | P16: =VLOOKUP(M16,Base!$A$3:$F$994, 2, false) -> . | T16: =VLOOKUP(M16,Base!$A$3:$F$994, 5, false) -> 0 | U16: =T16*O16 -> 0 | W16: =VLOOKUP(X16,Base!$A$3:$F$994, 6, false) -> 0 | X16: . | AA16: =VLOOKUP(X16,Base!$A$3:$F$994, 2, false) -> . | AE16: =VLOOKUP(X16,Base!$A$3:$F$994, 5, false) -> 0 | AF16: =AE16*Z16 -> 0 | AH16: =VLOOKUP(AI16,Base!$A$3:$F$994, 6, false) -> 0 | AI16: . | AL16: =VLOOKUP(AI16,Base!$A$3:$F$994, 2, false) -> . | AP16: =VLOOKUP(AI16,Base!$A$3:$F$994, 5, false) -> 0 | AQ16: =AP16*AK17 -> 0 | AS16: =VLOOKUP(AT16,Base!$A$3:$F$994, 6, false) -> 0 | AT16: . | AW16: =VLOOKUP(AT16,Base!$A$3:$F$994, 2, false) -> . | BA16: =VLOOKUP(AT16,Base!$A$3:$F$994, 5, false) -> 0 | BB16: =BA16*AV16 -> 0 | BD16: =VLOOKUP(BE16,Base!$A$3:$F$994, 6, false) -> 0 | BE16: . | BH16: =VLOOKUP(BE16,Base!$A$3:$F$994, 2, false) -> . | BL16: =VLOOKUP(BE16,Base!$A$3:$F$994, 5, false) -> 0 | BM16: =BL16*BG16 -> 0
A17: =VLOOKUP(B17,Base!$A$3:$F$994, 6, false) -> 0 | B17: . | E17: =VLOOKUP(B17,Base!$A$3:$F$994, 2, false) -> . | F17: PREPARACIÒN | I17: =VLOOKUP(B17,Base!$A$3:$F$994, 5, false) -> 0 | J17: =I17*D17 -> 0 | L17: =VLOOKUP(M17,Base!$A$3:$F$994, 6, false) -> 0 | M17: . | P17: =VLOOKUP(M17,Base!$A$3:$F$994, 2, false) -> . | Q17: PREPARACIÒN | T17: =VLOOKUP(M17,Base!$A$3:$F$994, 5, false) -> 0 | U17: =T17*O17 -> 0 | W17: =VLOOKUP(X17,Base!$A$3:$F$994, 6, false) -> 0 | X17: . | AA17: =VLOOKUP(X17,Base!$A$3:$F$994, 2, false) -> . | AB17: PREPARACIÒN | AE17: =VLOOKUP(X17,Base!$A$3:$F$994, 5, false) -> 0 | AF17: =AE17*Z17 -> 0 | AH17: =VLOOKUP(AI17,Base!$A$3:$F$994, 6, false) -> 0 | AI17: . | AL17: =VLOOKUP(AI17,Base!$A$3:$F$994, 2, false) -> . | AM17: PREPARACIÒN | AP17: =VLOOKUP(AI17,Base!$A$3:$F$994, 5, false) -> 0 | AQ17: =AP17*AK17 -> 0 | AS17: =VLOOKUP(AT17,Base!$A$3:$F$994, 6, false) -> 0 | AT17: . | AW17: =VLOOKUP(AT17,Base!$A$3:$F$994, 2, false) -> . | AX17: PREPARACIÒN | BA17: =VLOOKUP(AT17,Base!$A$3:$F$994, 5, false) -> 0 | BB17: =BA17*AV17 -> 0 | BD17: =VLOOKUP(BE17,Base!$A$3:$F$994, 6, false) -> 0 | BE17: . | BH17: =VLOOKUP(BE17,Base!$A$3:$F$994, 2, false) -> . | BI17: PREPARACIÒN | BL17: =VLOOKUP(BE17,Base!$A$3:$F$994, 5, false) -> 0 | BM17: =BL17*BG17 -> 0
A18: =VLOOKUP(B18,Base!$A$3:$F$994, 6, false) -> 0 | B18: . | E18: =VLOOKUP(B18,Base!$A$3:$F$994, 2, false) -> . | F18: Cortar zanahoria en juliana | I18: =VLOOKUP(B18,Base!$A$3:$F$994, 5, false) -> 0 | J18: =I18*D18 -> 0 | L18: =VLOOKUP(M18,Base!$A$3:$F$994, 6, false) -> 0 | M18: . | P18: =VLOOKUP(M18,Base!$A$3:$F$994, 2, false) -> . | T18: =VLOOKUP(M18,Base!$A$3:$F$994, 5, false) -> 0 | U18: =T18*O18 -> 0 | W18: =VLOOKUP(X18,Base!$A$3:$F$994, 6, false) -> 0 | X18: . | AA18: =VLOOKUP(X18,Base!$A$3:$F$994, 2, false) -> . | AE18: =VLOOKUP(X18,Base!$A$3:$F$994, 5, false) -> 0 | AF18: =AE18*Z18 -> 0 | AH18: =VLOOKUP(AI18,Base!$A$3:$F$994, 6, false) -> 0 | AI18: . | AL18: =VLOOKUP(AI18,Base!$A$3:$F$994, 2, false) -> . | AP18: =VLOOKUP(AI18,Base!$A$3:$F$994, 5, false) -> 0 | AQ18: =AP18*AK18 -> 0 | AS18: =VLOOKUP(AT18,Base!$A$3:$F$994, 6, false) -> 0 | AT18: . | AW18: =VLOOKUP(AT18,Base!$A$3:$F$994, 2, false) -> . | BA18: =VLOOKUP(AT18,Base!$A$3:$F$994, 5, false) -> 0 | BB18: =BA18*AV18 -> 0 | BD18: =VLOOKUP(BE18,Base!$A$3:$F$994, 6, false) -> 0 | BE18: . | BH18: =VLOOKUP(BE18,Base!$A$3:$F$994, 2, false) -> . | BL18: =VLOOKUP(BE18,Base!$A$3:$F$994, 5, false) -> 0 | BM18: =BL18*BG18 -> 0
A19: =VLOOKUP(B19,Base!$A$3:$F$994, 6, false) -> 0 | B19: . | E19: =VLOOKUP(B19,Base!$A$3:$F$994, 2, false) -> . | F19: Cortar chayote en brunoise | I19: =VLOOKUP(B19,Base!$A$3:$F$994, 5, false) -> 0 | J19: =I19*D19 -> 0 | L19: =VLOOKUP(M19,Base!$A$3:$F$994, 6, false) -> 0 | M19: . | P19: =VLOOKUP(M19,Base!$A$3:$F$994, 2, false) -> . | T19: =VLOOKUP(M19,Base!$A$3:$F$994, 5, false) -> 0 | U19: =T19*O19 -> 0 | W19: =VLOOKUP(X19,Base!$A$3:$F$994, 6, false) -> 0 | X19: . | AA19: =VLOOKUP(X19,Base!$A$3:$F$994, 2, false) -> . | AE19: =VLOOKUP(X19,Base!$A$3:$F$994, 5, false) -> 0 | AF19: =AE19*Z19 -> 0 | AH19: =VLOOKUP(AI19,Base!$A$3:$F$994, 6, false) -> 0 | AI19: . | AL19: =VLOOKUP(AI19,Base!$A$3:$F$994, 2, false) -> . | AP19: =VLOOKUP(AI19,Base!$A$3:$F$994, 5, false) -> 0 | AQ19: =AP19*AK19 -> 0 | AS19: =VLOOKUP(AT19,Base!$A$3:$F$994, 6, false) -> 0 | AT19: . | AW19: =VLOOKUP(AT19,Base!$A$3:$F$994, 2, false) -> . | BA19: =VLOOKUP(AT19,Base!$A$3:$F$994, 5, false) -> 0 | BB19: =BA19*AV19 -> 0 | BD19: =VLOOKUP(BE19,Base!$A$3:$F$994, 6, false) -> 0 | BE19: . | BH19: =VLOOKUP(BE19,Base!$A$3:$F$994, 2, false) -> . | BL19: =VLOOKUP(BE19,Base!$A$3:$F$994, 5, false) -> 0 | BM19: =BL19*BG19 -> 0
A20: =VLOOKUP(B20,Base!$A$3:$F$994, 6, false) -> 0 | B20: . | E20: =VLOOKUP(B20,Base!$A$3:$F$994, 2, false) -> . | I20: =VLOOKUP(B20,Base!$A$3:$F$994, 5, false) -> 0 | J20: =I20*D20 -> 0 | L20: =VLOOKUP(M20,Base!$A$3:$F$994, 6, false) -> 0 | M20: . | P20: =VLOOKUP(M20,Base!$A$3:$F$994, 2, false) -> . | T20: =VLOOKUP(M20,Base!$A$3:$F$994, 5, false) -> 0 | U20: =T20*O20 -> 0 | W20: =VLOOKUP(X20,Base!$A$3:$F$994, 6, false) -> 0 | X20: . | AA20: =VLOOKUP(X20,Base!$A$3:$F$994, 2, false) -> . | AE20: =VLOOKUP(X20,Base!$A$3:$F$994, 5, false) -> 0 | AF20: =AE20*Z20 -> 0 | AH20: =VLOOKUP(AI20,Base!$A$3:$F$994, 6, false) -> 0 | AI20: . | AL20: =VLOOKUP(AI20,Base!$A$3:$F$994, 2, false) -> . | AP20: =VLOOKUP(AI20,Base!$A$3:$F$994, 5, false) -> 0 | AQ20: =AP20*AK20 -> 0 | AS20: =VLOOKUP(AT20,Base!$A$3:$F$994, 6, false) -> 0 | AT20: . | AW20: =VLOOKUP(AT20,Base!$A$3:$F$994, 2, false) -> . | BA20: =VLOOKUP(AT20,Base!$A$3:$F$994, 5, false) -> 0 | BB20: =BA20*AV20 -> 0 | BD20: =VLOOKUP(BE20,Base!$A$3:$F$994, 6, false) -> 0 | BE20: . | BH20: =VLOOKUP(BE20,Base!$A$3:$F$994, 2, false) -> . | BL20: =VLOOKUP(BE20,Base!$A$3:$F$994, 5, false) -> 0 | BM20: =BL20*BG20 -> 0
A21: =VLOOKUP(B21,Base!$A$3:$F$994, 6, false) -> 0 | B21: . | E21: =VLOOKUP(B21,Base!$A$3:$F$994, 2, false) -> . | I21: =VLOOKUP(B21,Base!$A$3:$F$994, 5, false) -> 0 | J21: =I21*D21 -> 0 | L21: =VLOOKUP(M21,Base!$A$3:$F$994, 6, false) -> 0 | M21: . | P21: =VLOOKUP(M21,Base!$A$3:$F$994, 2, false) -> . | T21: =VLOOKUP(M21,Base!$A$3:$F$994, 5, false) -> 0 | U21: =T21*O21 -> 0 | W21: =VLOOKUP(X21,Base!$A$3:$F$994, 6, false) -> 0 | X21: . | AA21: =VLOOKUP(X21,Base!$A$3:$F$994, 2, false) -> . | AE21: =VLOOKUP(X21,Base!$A$3:$F$994, 5, false) -> 0 | AF21: =AE21*Z21 -> 0 | AH21: =VLOOKUP(AI21,Base!$A$3:$F$994, 6, false) -> 0 | AI21: . | AL21: =VLOOKUP(AI21,Base!$A$3:$F$994, 2, false) -> . | AP21: =VLOOKUP(AI21,Base!$A$3:$F$994, 5, false) -> 0 | AQ21: =AP21*AK21 -> 0 | AS21: =VLOOKUP(AT21,Base!$A$3:$F$994, 6, false) -> 0 | AT21: . | AW21: =VLOOKUP(AT21,Base!$A$3:$F$994, 2, false) -> . | BA21: =VLOOKUP(AT21,Base!$A$3:$F$994, 5, false) -> 0 | BB21: =BA21*AV21 -> 0 | BD21: =VLOOKUP(BE21,Base!$A$3:$F$994, 6, false) -> 0 | BE21: . | BH21: =VLOOKUP(BE21,Base!$A$3:$F$994, 2, false) -> . | BL21: =VLOOKUP(BE21,Base!$A$3:$F$994, 5, false) -> 0 | BM21: =BL21*BG21 -> 0
A22: =VLOOKUP(B22,Base!$A$3:$F$994, 6, false) -> 0 | B22: . | E22: =VLOOKUP(B22,Base!$A$3:$F$994, 2, false) -> . | I22: =VLOOKUP(B22,Base!$A$3:$F$994, 5, false) -> 0 | J22: =I22*D22 -> 0 | L22: =VLOOKUP(M22,Base!$A$3:$F$994, 6, false) -> 0 | M22: . | P22: =VLOOKUP(M22,Base!$A$3:$F$994, 2, false) -> . | T22: =VLOOKUP(M22,Base!$A$3:$F$994, 5, false) -> 0 | U22: =T22*O22 -> 0 | W22: =VLOOKUP(X22,Base!$A$3:$F$994, 6, false) -> 0 | X22: . | AA22: =VLOOKUP(X22,Base!$A$3:$F$994, 2, false) -> . | AE22: =VLOOKUP(X22,Base!$A$3:$F$994, 5, false) -> 0 | AF22: =AE22*Z22 -> 0 | AH22: =VLOOKUP(AI22,Base!$A$3:$F$994, 6, false) -> 0 | AI22: . | AL22: =VLOOKUP(AI22,Base!$A$3:$F$994, 2, false) -> . | AP22: =VLOOKUP(AI22,Base!$A$3:$F$994, 5, false) -> 0 | AQ22: =AP22*AK22 -> 0 | AS22: =VLOOKUP(AT22,Base!$A$3:$F$994, 6, false) -> 0 | AT22: . | AW22: =VLOOKUP(AT22,Base!$A$3:$F$994, 2, false) -> . | BA22: =VLOOKUP(AT22,Base!$A$3:$F$994, 5, false) -> 0 | BB22: =BA22*AV22 -> 0 | BD22: =VLOOKUP(BE22,Base!$A$3:$F$994, 6, false) -> 0 | BE22: . | BH22: =VLOOKUP(BE22,Base!$A$3:$F$994, 2, false) -> . | BL22: =VLOOKUP(BE22,Base!$A$3:$F$994, 5, false) -> 0 | BM22: =BL22*BG22 -> 0
A23: =VLOOKUP(B23,Base!$A$3:$F$994, 6, false) -> 0 | B23: . | E23: =VLOOKUP(B23,Base!$A$3:$F$994, 2, false) -> . | I23: =VLOOKUP(B23,Base!$A$3:$F$994, 5, false) -> 0 | J23: =I23*D23 -> 0 | L23: =VLOOKUP(M23,Base!$A$3:$F$994, 6, false) -> 0 | M23: . | P23: =VLOOKUP(M23,Base!$A$3:$F$994, 2, false) -> . | T23: =VLOOKUP(M23,Base!$A$3:$F$994, 5, false) -> 0 | U23: =T23*O23 -> 0 | W23: =VLOOKUP(X23,Base!$A$3:$F$994, 6, false) -> 0 | X23: . | AA23: =VLOOKUP(X23,Base!$A$3:$F$994, 2, false) -> . | AE23: =VLOOKUP(X23,Base!$A$3:$F$994, 5, false) -> 0 | AF23: =AE23*Z23 -> 0 | AH23: =VLOOKUP(AI23,Base!$A$3:$F$994, 6, false) -> 0 | AI23: . | AL23: =VLOOKUP(AI23,Base!$A$3:$F$994, 2, false) -> . | AP23: =VLOOKUP(AI23,Base!$A$3:$F$994, 5, false) -> 0 | AQ23: =AP23*AK23 -> 0 | AS23: =VLOOKUP(AT23,Base!$A$3:$F$994, 6, false) -> 0 | AT23: . | AW23: =VLOOKUP(AT23,Base!$A$3:$F$994, 2, false) -> . | BA23: =VLOOKUP(AT23,Base!$A$3:$F$994, 5, false) -> 0 | BB23: =BA23*AV23 -> 0 | BD23: =VLOOKUP(BE23,Base!$A$3:$F$994, 6, false) -> 0 | BE23: . | BH23: =VLOOKUP(BE23,Base!$A$3:$F$994, 2, false) -> . | BL23: =VLOOKUP(BE23,Base!$A$3:$F$994, 5, false) -> 0 | BM23: =BL23*BG23 -> 0
A24: =VLOOKUP(B24,Base!$A$3:$F$994, 6, false) -> 0 | B24: . | E24: =VLOOKUP(B24,Base!$A$3:$F$994, 2, false) -> . | I24: =VLOOKUP(B24,Base!$A$3:$F$994, 5, false) -> 0 | J24: =I24*D24 -> 0 | L24: =VLOOKUP(M24,Base!$A$3:$F$994, 6, false) -> 0 | M24: . | P24: =VLOOKUP(M24,Base!$A$3:$F$994, 2, false) -> . | T24: =VLOOKUP(M24,Base!$A$3:$F$994, 5, false) -> 0 | U24: =T24*O24 -> 0 | W24: =VLOOKUP(X24,Base!$A$3:$F$994, 6, false) -> 0 | X24: . | AA24: =VLOOKUP(X24,Base!$A$3:$F$994, 2, false) -> . | AE24: =VLOOKUP(X24,Base!$A$3:$F$994, 5, false) -> 0 | AF24: =AE24*Z24 -> 0 | AH24: =VLOOKUP(AI24,Base!$A$3:$F$994, 6, false) -> 0 | AI24: . | AL24: =VLOOKUP(AI24,Base!$A$3:$F$994, 2, false) -> . | AP24: =VLOOKUP(AI24,Base!$A$3:$F$994, 5, false) -> 0 | AQ24: =AP24*AK24 -> 0 | AS24: =VLOOKUP(AT24,Base!$A$3:$F$994, 6, false) -> 0 | AT24: . | AW24: =VLOOKUP(AT24,Base!$A$3:$F$994, 2, false) -> . | BA24: =VLOOKUP(AT24,Base!$A$3:$F$994, 5, false) -> 0 | BB24: =BA24*AV24 -> 0 | BD24: =VLOOKUP(BE24,Base!$A$3:$F$994, 6, false) -> 0 | BE24: . | BH24: =VLOOKUP(BE24,Base!$A$3:$F$994, 2, false) -> . | BL24: =VLOOKUP(BE24,Base!$A$3:$F$994, 5, false) -> 0 | BM24: =BL24*BG24 -> 0
A25: ELABORACIÒN | I25: TOTAL DE MP: | J25: =SUM(J7:J24) -> #N/A | L25: ELABORACIÒN | T25: TOTAL DE MP: | U25: =SUM(U7:U24) -> 0 | W25: ELABORACIÒN | AE25: TOTAL DE MP: | AF25: =SUM(AF7:AF24) -> 0 | AH25: ELABORACIÒN | AP25: TOTAL DE MP: | AQ25: =SUM(AQ7:AQ24) -> 0 | AS25: ELABORACIÒN | BA25: TOTAL DE MP: | BB25: =SUM(BB7:BB24) -> 0 | BD25: ELABORACIÒN | BL25: TOTAL DE MP: | BM25: =SUM(BM7:BM24) -> 0
A26: Cocinar la juliana de zanahoria en agua hirbo | I26: TOTAL P/P: | J26: =J25/E5 -> #N/A | T26: TOTAL P/P: | U26: =U25/P5 -> 0 | AE26: TOTAL P/P: | AF26: =AF25/AA5 -> 0 | AP26: TOTAL P/P: | AQ26: =AQ25/AL5 -> 0 | BA26: TOTAL P/P: | BB26: =BB25/AW5 -> 0 | BL26: TOTAL P/P: | BM26: =BM25/BH5 -> 0
I27: IMPREVISTO: | J27: 0.05 | T27: IMPREVISTO: | U27: 0.05 | AE27: IMPREVISTO: | AF27: 0.05 | AP27: IMPREVISTO: | AQ27: 0.05 | BA27: IMPREVISTO: | BB27: 0.05 | BL27: IMPREVISTO: | BM27: 0.05
I28: TOTAL DE COSTO: | J28: =J26+(J26*J27) -> #N/A | T28: TOTAL DE COSTO: | U28: =U26+(U26*U27) -> 0 | AE28: TOTAL DE COSTO: | AF28: =AF26+(AF26*AF27) -> 0 | AP28: TOTAL DE COSTO: | AQ28: =AQ26+(AQ26*AQ27) -> 0 | BA28: TOTAL DE COSTO: | BB28: =BB26+(BB26*BB27) -> 0 | BL28: TOTAL DE COSTO: | BM28: =BM26+(BM26*BM27) -> 0
I29: PRECIO SUGERIDO: | J29: =J28*I5 -> #N/A | T29: PRECIO SUGERIDO: | U29: =U28*T5 -> 0 | AE29: PRECIO SUGERIDO: | AF29: =AF28*AE5 -> 0 | AP29: PRECIO SUGERIDO: | AQ29: =AQ28*AP5 -> 0 | BA29: PRECIO SUGERIDO: | BB29: =BB28*BA5 -> 0 | BL29: PRECIO SUGERIDO: | BM29: =BM28*BL5 -> 0
I30: IVA: | J30: =J31-J29 -> #N/A | T30: IVA: | U30: =U31-U29 -> 0 | AE30: IVA: | AF30: =AF31-AF29 -> 0 | AP30: IVA: | AQ30: =AQ31-AQ29 -> 0 | BA30: IVA: | BB30: =BB31-BB29 -> 0 | BL30: IVA: | BM30: =BM31-BM29 -> 0
I31: PRECIO SUGERIDO CON IVA: | J31: =J29*(J3*1+1) -> #N/A | T31: PRECIO SUGERIDO CON IVA: | U31: =U29*(U3*1+1) -> 0 | AE31: PRECIO SUGERIDO CON IVA: | AF31: =AF29*(AF3*1+1) -> 0 | AP31: PRECIO SUGERIDO CON IVA: | AQ31: =AQ29*(AQ3*1+1) -> 0 | BA31: PRECIO SUGERIDO CON IVA: | BB31: =BB29*(BB3*1+1) -> 0 | BL31: PRECIO SUGERIDO CON IVA: | BM31: =BM29*(BM3*1+1) -> 0
I32: AJUSTE A LA CARTA | T32: AJUSTE A LA CARTA | AE32: AJUSTE A LA CARTA | AP32: AJUSTE A LA CARTA | BA32: AJUSTE A LA CARTA | BL32: AJUSTE A LA CARTA
I33: PRECIO AJUSTADO: | J33: 50 | T33: PRECIO AJUSTADO: | AE33: PRECIO AJUSTADO: | AP33: PRECIO AJUSTADO: | BA33: PRECIO AJUSTADO: | BL33: PRECIO AJUSTADO:
A34: MONTAJE | I34: IVA: | J34: =J33-J35 -> 6.8965517 | L34: MONTAJE | T34: IVA: | U34: =U33-U35 -> 0 | W34: MONTAJE | AE34: IVA: | AF34: =AF33-AF35 -> 0 | AH34: MONTAJE | AP34: IVA: | AQ34: =AQ33-AQ35 -> 0 | AS34: MONTAJE | BA34: IVA: | BB34: =BB33-BB35 -> 0 | BD34: MONTAJE | BL34: IVA: | BM34: =BM33-BM35 -> 0
A35: Pineri | I35: PRECIO AJUSTADO SIN IVA: | J35: =J33/(J3*1+1) -> 43.103448 | T35: PRECIO AJUSTADO SIN IVA: | U35: =U33/(U3*1+1) -> 0 | AE35: PRECIO AJUSTADO SIN IVA: | AF35: =AF33/(AF3*1+1) -> 0 | AP35: PRECIO AJUSTADO SIN IVA: | AQ35: =AQ33/(AQ3*1+1) -> 0 | BA35: PRECIO AJUSTADO SIN IVA: | BB35: =BB33/(BB3*1+1) -> 0 | BL35: PRECIO AJUSTADO SIN IVA: | BM35: =BM33/(BM3*1+1) -> 0
I36: NUEVO % DE COSTO: | J36: =J28/J35 -> #N/A | T36: NUEVO % DE COSTO: | U36: =U28/U35 -> #DIV/0! | AE36: NUEVO % DE COSTO: | AF36: =AF28/AF35 -> #DIV/0! | AP36: NUEVO % DE COSTO: | AQ36: =AQ28/AQ35 -> #DIV/0! | BA36: NUEVO % DE COSTO: | BB36: =BB28/BB35 -> #DIV/0! | BL36: NUEVO % DE COSTO: | BM36: =BM28/BM35 -> #DIV/0!
I37: NUEVO FACTOR DE VENTA: | J37: =J35/J28 -> #N/A | T37: NUEVO FACTOR DE VENTA: | U37: =U35/U28 -> #DIV/0! | AE37: NUEVO FACTOR DE VENTA: | AF37: =AF35/AF28 -> #DIV/0! | AP37: NUEVO FACTOR DE VENTA: | AQ37: =AQ35/AQ28 -> #DIV/0! | BA37: NUEVO FACTOR DE VENTA: | BB37: =BB35/BB28 -> #DIV/0! | BL37: NUEVO FACTOR DE VENTA: | BM37: =BM35/BM28 -> #DIV/0!
A38: OBSERVACIONES | L38: OBSERVACIONES | W38: OBSERVACIONES | AH38: OBSERVACIONES | AS38: OBSERVACIONES | BD38: OBSERVACIONES
I46: IMPUESTO | J46: =$J$3 -> 0.16 | T46: IMPUESTO: | U46: =$J$3 -> 0.16 | AE46: IMPUESTO: | AF46: =$J$3 -> 0.16 | AP46: IMPUESTO: | AQ46: =$J$3 -> 0.16 | BA46: IMPUESTO: | BB46: =$J$3 -> 0.16 | BL46: IMPUESTO: | BM46: =$J$3 -> 0.16
A47: NOMBRE: | F47: FECHA: | G47: =$G$4 -> 42399 | I47: FACTOR DE VENTA | J47: % DE COSTO | L47: NOMBRE: | Q47: FECHA: | R47: =$G$4 -> 42399 | T47: FACTOR DE VENTA | U47: % DE COSTO | W47: NOMBRE: | AB47: FECHA: | AC47: =$G$4 -> 42399 | AE47: FACTOR DE VENTA | AF47: % DE COSTO | AH47: NOMBRE: | AM47: FECHA: | AN47: =$G$4 -> 42399 | AP47: FACTOR DE VENTA | AQ47: % DE COSTO | AS47: NOMBRE: | AX47: FECHA: | AY47: =$G$4 -> 42399 | BA47: FACTOR DE VENTA | BB47: % DE COSTO | BD47: NOMBRE: | BI47: FECHA: | BJ47: =$G$4 -> 42399 | BL47: FACTOR DE VENTA | BM47: % DE COSTO
...

Sheet COSTEO COPEO Y BOTELLA
A1: NOMBRE DEL ESTABLECIMIENTO
A3: COSTEO DE BEBIDAS POR BOTELLA
A4: Código | B4: ArtÍculo | C4: Capacidad (L) | D4: Costo unitario | E4: Factor | F4: Precio de venta | G4: IVA | H4: Precio sugerido a la carta | I4: Ajuste a la carta | J4: Ajuste s/IVA | K4: IVA | L4: Nuevo % de costo | M4: Nuevo Factor
A5: =vlookup(B5,Base!$A$3:$F$994, 6, false) -> 0 | B5: . | C5: =VLOOKUP(B5,Base!$A$3:$F$994, 3, FALSE) -> . | D5: =VLOOKUP(B5,Base!$A$3:$F$994, 4, FALSE) -> . | F5: =E5*D5 -> #VALUE! | G5: =H5-F5 -> #VALUE! | H5: =F5*1.16 -> #VALUE! | J5: =I5/1.16 -> 0 | K5: =I5-J5 -> 0 | L5: =D5/J5 -> #VALUE! | M5: =J5/D5 -> #VALUE!
A6: =vlookup(B6,Base!$A$3:$F$994, 6, false) -> 0 | B6: . | C6: =VLOOKUP(B6,Base!$A$3:$F$994, 3, FALSE) -> . | D6: =VLOOKUP(B6,Base!$A$3:$F$994, 4, FALSE) -> . | F6: =E6*D6 -> #VALUE! | G6: =H6-F6 -> #VALUE! | H6: =F6*1.16 -> #VALUE! | J6: =I6/1.16 -> 0 | K6: =I6-J6 -> 0 | L6: =D6/J6 -> #VALUE! | M6: =J6/D6 -> #VALUE!
A7: =vlookup(B7,Base!$A$3:$F$994, 6, false) -> 0 | B7: . | C7: =VLOOKUP(B7,Base!$A$3:$F$994, 3, FALSE) -> . | D7: =VLOOKUP(B7,Base!$A$3:$F$994, 4, FALSE) -> . | F7: =E7*D7 -> #VALUE! | G7: =H7-F7 -> #VALUE! | H7: =F7*1.16 -> #VALUE! | J7: =I7/1.16 -> 0 | K7: =I7-J7 -> 0 | L7: =D7/J7 -> #VALUE! | M7: =J7/D7 -> #VALUE!
A8: =vlookup(B8,Base!$A$3:$F$994, 6, false) -> 0 | B8: . | C8: =VLOOKUP(B8,Base!$A$3:$F$994, 3, FALSE) -> . | D8: =VLOOKUP(B8,Base!$A$3:$F$994, 4, FALSE) -> . | F8: =E8*D8 -> #VALUE! | G8: =H8-F8 -> #VALUE! | H8: =F8*1.16 -> #VALUE! | J8: =I8/1.16 -> 0 | K8: =I8-J8 -> 0 | L8: =D8/J8 -> #VALUE! | M8: =J8/D8 -> #VALUE!
A9: =vlookup(B9,Base!$A$3:$F$994, 6, false) -> 0 | B9: . | C9: =VLOOKUP(B9,Base!$A$3:$F$994, 3, FALSE) -> . | D9: =VLOOKUP(B9,Base!$A$3:$F$994, 4, FALSE) -> . | F9: =E9*D9 -> #VALUE! | G9: =H9-F9 -> #VALUE! | H9: =F9*1.16 -> #VALUE! | J9: =I9/1.16 -> 0 | K9: =I9-J9 -> 0 | L9: =D9/J9 -> #VALUE! | M9: =J9/D9 -> #VALUE!
A10: =vlookup(B10,Base!$A$3:$F$994, 6, false) -> 0 | B10: . | C10: =VLOOKUP(B10,Base!$A$3:$F$994, 3, FALSE) -> . | D10: =VLOOKUP(B10,Base!$A$3:$F$994, 4, FALSE) -> . | F10: =E10*D10 -> #VALUE! | G10: =H10-F10 -> #VALUE! | H10: =F10*1.16 -> #VALUE! | J10: =I10/1.16 -> 0 | K10: =I10-J10 -> 0 | L10: =D10/J10 -> #VALUE! | M10: =J10/D10 -> #VALUE!
A11: =vlookup(B11,Base!$A$3:$F$994, 6, false) -> 0 | B11: . | C11: =VLOOKUP(B11,Base!$A$3:$F$994, 3, FALSE) -> . | D11: =VLOOKUP(B11,Base!$A$3:$F$994, 4, FALSE) -> . | F11: =E11*D11 -> #VALUE! | G11: =H11-F11 -> #VALUE! | H11: =F11*1.16 -> #VALUE! | J11: =I11/1.16 -> 0 | K11: =I11-J11 -> 0 | L11: =D11/J11 -> #VALUE! | M11: =J11/D11 -> #VALUE!
A12: =vlookup(B12,Base!$A$3:$F$994, 6, false) -> 0 | B12: . | C12: =VLOOKUP(B12,Base!$A$3:$F$994, 3, FALSE) -> . | D12: =VLOOKUP(B12,Base!$A$3:$F$994, 4, FALSE) -> . | F12: =E12*D12 -> #VALUE! | G12: =H12-F12 -> #VALUE! | H12: =F12*1.16 -> #VALUE! | J12: =I12/1.16 -> 0 | K12: =I12-J12 -> 0 | L12: =D12/J12 -> #VALUE! | M12: =J12/D12 -> #VALUE!
A13: =vlookup(B13,Base!$A$3:$F$994, 6, false) -> 0 | B13: . | C13: =VLOOKUP(B13,Base!$A$3:$F$994, 3, FALSE) -> . | D13: =VLOOKUP(B13,Base!$A$3:$F$994, 4, FALSE) -> . | F13: =E13*D13 -> #VALUE! | G13: =H13-F13 -> #VALUE! | H13: =F13*1.16 -> #VALUE! | J13: =I13/1.16 -> 0 | K13: =I13-J13 -> 0 | L13: =D13/J13 -> #VALUE! | M13: =J13/D13 -> #VALUE!
A14: =vlookup(B14,Base!$A$3:$F$994, 6, false) -> 0 | B14: . | C14: =VLOOKUP(B14,Base!$A$3:$F$994, 3, FALSE) -> . | D14: =VLOOKUP(B14,Base!$A$3:$F$994, 4, FALSE) -> . | F14: =E14*D14 -> #VALUE! | G14: =H14-F14 -> #VALUE! | H14: =F14*1.16 -> #VALUE! | J14: =I14/1.16 -> 0 | K14: =I14-J14 -> 0 | L14: =D14/J14 -> #VALUE! | M14: =J14/D14 -> #VALUE!
A15: =vlookup(B15,Base!$A$3:$F$994, 6, false) -> 0 | B15: . | C15: =VLOOKUP(B15,Base!$A$3:$F$994, 3, FALSE) -> . | D15: =VLOOKUP(B15,Base!$A$3:$F$994, 4, FALSE) -> . | F15: =E15*D15 -> #VALUE! | G15: =H15-F15 -> #VALUE! | H15: =F15*1.16 -> #VALUE! | J15: =I15/1.16 -> 0 | K15: =I15-J15 -> 0 | L15: =D15/J15 -> #VALUE! | M15: =J15/D15 -> #VALUE!
A16: =vlookup(B16,Base!$A$3:$F$994, 6, false) -> 0 | B16: . | C16: =VLOOKUP(B16,Base!$A$3:$F$994, 3, FALSE) -> . | D16: =VLOOKUP(B16,Base!$A$3:$F$994, 4, FALSE) -> . | F16: =E16*D16 -> #VALUE! | G16: =H16-F16 -> #VALUE! | H16: =F16*1.16 -> #VALUE! | J16: =I16/1.16 -> 0 | K16: =I16-J16 -> 0 | L16: =D16/J16 -> #VALUE! | M16: =J16/D16 -> #VALUE!
... A44: =vlookup(B44,Base!$A$3:$F$994, 6, false) -> 0 | B44: . | C44: =VLOOKUP(B44,Base!$A$3:$F$994, 3, FALSE) -> . | D44: =VLOOKUP(B44,Base!$A$3:$F$994, 4, FALSE) -> . | F44: =E44*D44 -> #VALUE! | G44: =H44-F44 -> #VALUE! | H44: =F44*1.16 -> #VALUE! | J44: =I44/1.16 -> 0 | K44: =I44-J44 -> 0 | L44: =D44/J44 -> #VALUE! | M44: =J44/D44 -> #VALUE!
A47: COSTEO DE BEBIDAS POR COPEO
A48: Código | B48: ArtÍculo | C48: Capacidad (L) | D48: Costo unitario | E48: Número de copas | F48: Costo por copa | G48: Mezclador | H48: Total de costo | I48: Factor | J48: Precio de venta | K48: IVA | L48: Precio sugerido a la carta | M48: Ajuste a la carta | N48: Ajuste s/IVA | O48: IVA | P48: Nuevo % de costo | Q48: Nuevo Factor
